Workbook

Sheet Cover
B4: 롯데관광개발 (드림타워 카지노)
D6: 본 자료는 롯데관광개발 드림타워 카지노의 월별 영업실적입니다. 본 자료는 외부감사인의 검토가 완료되지 않은 상태에서 투자자 편의를 위하여 작성된 자료이며, 본자료의 일부는 감사인의 검토 과정에서 일부 변경될 수 있습니다. 이러한 불확실성으로 인해 회사의 실제 실적은 본 자료에 명시되어 있거나, 묵시적으로 포함된 내용과 차이가 있을 수 있음을 양지하여 주시기 바랍니다. 본 자료는 롯데관광개발의 사전 서면 승인 없이 어떤 형식으로도 배포 또는 수정할 수 없습니다. 또한, 해당 정보는 외부 환경 혹은 사업 여건 등의 변경에 따라 별도의 공지 없이 수정될 수 있음을 알려드립니다.

Sheet DreamtowerCasino
H2: ↓ 수식 | M2: (단위 : 백만원, %, 명) | O2: y-y | Z2: (단위 : 백만원, %, 명)
B3: 월 | C3: 카지노 드롭액 | F3: 카지노 홀드율 | I3: 카지노 순매출 | L3: 카지노 방문객 | M3: 호텔 매출액 | O3: 월 | P3: 카지노 드롭액 | S3: 카지노 홀드율 | V3: 카지노 순매출 | Y3: 카지노 방문객 | Z3: 호텔 매출액
C4: 테이블 | D4: 머신 | E4: 총계 | F4: 테이블 | G4: 머신 | H4: 총계 | I4: 테이블 | J4: 머신 | K4: 총계 | P4: 테이블 | Q4: 머신 | R4: 총계 | S4: 테이블 | T4: 머신 | U4: 총계 | V4: 테이블 | W4: 머신 | X4: 총계
B5: 44348 | C5: 21080 | D5: 3349 | E5: 24429 | F5: 0.142 | G5: 0.015 | H5: =K5/E5 -> 0.12476974 | I5: 2999 | J5: 50 | K5: 3048 | L5: 6940 | O5: 44348
B6: 44378 | C6: 30180 | D6: 4391 | E6: 34571 | F6: 0.016 | G6: 0.109 | H6: =K6/E6 -> 0.028000347 | I6: 488 | J6: 480 | K6: 968 | L6: 8996 | O6: 44378
B7: 44409 | C7: 25563 | D7: 4029 | E7: 29592 | F7: 0.159 | G7: 0.106 | H7: =K7/E7 -> 0.15162882 | I7: 4058 | J7: 429 | K7: 4487 | L7: 7513 | O7: 44409
B8: 44440 | C8: 15937 | D8: 2637 | E8: 18574 | F8: 0.164 | G8: 0.031 | H8: =K8/E8 -> 0.145526 | I8: 2621 | J8: 83 | K8: 2703 | L8: 6228 | O8: 44440
B9: 44470 | C9: 15678 | D9: 2569 | E9: 18247 | F9: 0.122 | G9: 0.061 | H9: =K9/E9 -> 0.1133885 | I9: 1913 | J9: 156 | K9: 2069 | L9: 8072 | O9: 44470
B10: 44501 | C10: 21342 | D10: 2532 | E10: 23874 | F10: 0.077 | G10: 0.08 | H10: =K10/E10 -> 0.077532043 | I10: 1648 | J10: 204 | K10: 1851 | L10: 7201 | O10: 44501
B11: 44531 | C11: 25635 | D11: 2202 | E11: 27837 | F11: 0.222 | G11: 0.095 | H11: =K11/E11 -> 0.21201997 | I11: 5694 | J11: 208 | K11: 5902 | L11: 4997 | O11: 44531
B12: 44562 | C12: 37145 | D12: 3649 | E12: 40795 | F12: 0.018 | G12: 0.079 | H12: =K12/E12 -> 0.023042039 | I12: 650 | J12: 290 | K12: 940 | L12: 5207 | O12: 44562
B13: 44593 | C13: 39835 | D13: 3483 | E13: 43318 | F13: 0.058 | G13: 0.085 | H13: =K13/E13 -> 0.059928898 | I13: 2301 | J13: 295 | K13: 2596 | L13: 4699 | O13: 44593
B14: 44621 | C14: 28373 | D14: 3160 | E14: 31532 | F14: 0.306 | G14: 0.021 | H14: =K14/E14 -> 0.27759102 | I14: 8686 | J14: 67 | K14: 8753 | L14: 4399 | O14: 44621
B15: 44652 | C15: 27292 | D15: 4681 | E15: 31974 | F15: 0.065 | G15: 0.076 | H15: =K15/E15 -> 0.066460249 | I15: 1769 | J15: 355 | K15: 2125 | L15: 5070 | M15: 9521 | O15: 44652
B16: 44682 | C16: 28389 | D16: 4494 | E16: 32884 | F16: 0.128 | G16: 0.094 | H16: =K16/E16 -> 0.12337307 | I16: 3634 | J16: 424 | K16: 4057 | L16: 7142 | M16: 10958 | O16: 44682
B17: 44713 | C17: 26917 | D17: 5774 | E17: 32691 | F17: 0.206 | G17: 0.09 | H17: =K17/E17 -> 0.18512741 | I17: 5532 | J17: 520 | K17: 6052 | L17: 7491 | M17: 10562 | O17: 44713 | P17: =IF(AND(C5<=0,C17>0),"흑전",IF(AND(C5<=0,C17<=0),"적지",IF(AND(C5>0,C17<=0),"적전",C17/C5-1))) -> 0.27689753 | Q17: =IF(AND(D5<=0,D17>0),"흑전",IF(AND(D5<=0,D17<=0),"적지",IF(AND(D5>0,D17<=0),"적전",D17/D5-1))) -> 0.72409675 | R17: =IF(AND(E5<=0,E17>0),"흑전",IF(AND(E5<=0,E17<=0),"적지",IF(AND(E5>0,E17<=0),"적전",E17/E5-1))) -> 0.33820459 | S17: =IF(AND(F5<=0,F17>0),"흑전",IF(AND(F5<=0,F17<=0),"적지",IF(AND(F5>0,F17<=0),"적전",F17/F5-1))) -> 0.45070423 | T17: =IF(AND(G5<=0,G17>0),"흑전",IF(AND(G5<=0,G17<=0),"적지",IF(AND(G5>0,G17<=0),"적전",G17/G5-1))) -> 5 | U17: =IF(AND(H5<=0,H17>0),"흑전",IF(AND(H5<=0,H17<=0),"적지",IF(AND(H5>0,H17<=0),"적전",H17/H5-1))) -> 0.48375242 | V17: =IF(AND(I5<=0,I17>0),"흑전",IF(AND(I5<=0,I17<=0),"적지",IF(AND(I5>0,I17<=0),"적전",I17/I5-1))) -> 0.84461487 | W17: =IF(AND(J5<=0,J17>0),"흑전",IF(AND(J5<=0,J17<=0),"적지",IF(AND(J5>0,J17<=0),"적전",J17/J5-1))) -> 9.4 | ... Y17: =IF(AND(L5<=0,L17>0),"흑전",IF(AND(L5<=0,L17<=0),"적지",IF(AND(L5>0,L17<=0),"적전",L17/L5-1))) -> 0.079394813
B18: 44743 | C18: 24597 | D18: 6486 | E18: 31084 | F18: 0.108 | G18: 0.091 | H18: =K18/E18 -> 0.10490928 | I18: 2668 | J18: 593 | K18: 3261 | L18: 7734 | M18: 11240 | O18: 44743 | P18: =IF(AND(C6<=0,C18>0),"흑전",IF(AND(C6<=0,C18<=0),"적지",IF(AND(C6>0,C18<=0),"적전",C18/C6-1))) -> -0.18499006 | Q18: =IF(AND(D6<=0,D18>0),"흑전",IF(AND(D6<=0,D18<=0),"적지",IF(AND(D6>0,D18<=0),"적전",D18/D6-1))) -> 0.47711228 | R18: =IF(AND(E6<=0,E18>0),"흑전",IF(AND(E6<=0,E18<=0),"적지",IF(AND(E6>0,E18<=0),"적전",E18/E6-1))) -> -0.10086489 | S18: =IF(AND(F6<=0,F18>0),"흑전",IF(AND(F6<=0,F18<=0),"적지",IF(AND(F6>0,F18<=0),"적전",F18/F6-1))) -> 5.75 | T18: =IF(AND(G6<=0,G18>0),"흑전",IF(AND(G6<=0,G18<=0),"적지",IF(AND(G6>0,G18<=0),"적전",G18/G6-1))) -> -0.16513761 | U18: =IF(AND(H6<=0,H18>0),"흑전",IF(AND(H6<=0,H18<=0),"적지",IF(AND(H6>0,H18<=0),"적전",H18/H6-1))) -> 2.7467135 | V18: =IF(AND(I6<=0,I18>0),"흑전",IF(AND(I6<=0,I18<=0),"적지",IF(AND(I6>0,I18<=0),"적전",I18/I6-1))) -> 4.4672131 | W18: =IF(AND(J6<=0,J18>0),"흑전",IF(AND(J6<=0,J18<=0),"적지",IF(AND(J6>0,J18<=0),"적전",J18/J6-1))) -> 0.23541667 | ... Y18: =IF(AND(L6<=0,L18>0),"흑전",IF(AND(L6<=0,L18<=0),"적지",IF(AND(L6>0,L18<=0),"적전",L18/L6-1))) -> -0.14028457
B19: 44774 | C19: 42828 | D19: 8421 | E19: 51250 | F19: 0.078 | G19: 0.074 | H19: =K19/E19 -> 0.07715122 | I19: 3331 | J19: 623 | K19: 3954 | L19: 8657 | M19: 11847 | O19: 44774 | P19: =IF(AND(C7<=0,C19>0),"흑전",IF(AND(C7<=0,C19<=0),"적지",IF(AND(C7>0,C19<=0),"적전",C19/C7-1))) -> 0.67539021 | Q19: =IF(AND(D7<=0,D19>0),"흑전",IF(AND(D7<=0,D19<=0),"적지",IF(AND(D7>0,D19<=0),"적전",D19/D7-1))) -> 1.0900968 | R19: =IF(AND(E7<=0,E19>0),"흑전",IF(AND(E7<=0,E19<=0),"적지",IF(AND(E7>0,E19<=0),"적전",E19/E7-1))) -> 0.731887 | S19: =IF(AND(F7<=0,F19>0),"흑전",IF(AND(F7<=0,F19<=0),"적지",IF(AND(F7>0,F19<=0),"적전",F19/F7-1))) -> -0.50943396 | T19: =IF(AND(G7<=0,G19>0),"흑전",IF(AND(G7<=0,G19<=0),"적지",IF(AND(G7>0,G19<=0),"적전",G19/G7-1))) -> -0.30188679 | U19: =IF(AND(H7<=0,H19>0),"흑전",IF(AND(H7<=0,H19<=0),"적지",IF(AND(H7>0,H19<=0),"적전",H19/H7-1))) -> -0.49118367 | V19: =IF(AND(I7<=0,I19>0),"흑전",IF(AND(I7<=0,I19<=0),"적지",IF(AND(I7>0,I19<=0),"적전",I19/I7-1))) -> -0.17915229 | W19: =IF(AND(J7<=0,J19>0),"흑전",IF(AND(J7<=0,J19<=0),"적지",IF(AND(J7>0,J19<=0),"적전",J19/J7-1))) -> 0.45221445 | ... Y19: =IF(AND(L7<=0,L19>0),"흑전",IF(AND(L7<=0,L19<=0),"적지",IF(AND(L7>0,L19<=0),"적전",L19/L7-1))) -> 0.1522694
B20: 44805 | C20: 61863 | D20: 7274 | E20: 69137 | F20: 0.046 | G20: 0.057 | H20: =K20/E20 -> 0.04752882 | I20: 2868 | J20: 417 | K20: 3286 | L20: 8468 | M20: 8557 | O20: 44805 | P20: =IF(AND(C8<=0,C20>0),"흑전",IF(AND(C8<=0,C20<=0),"적지",IF(AND(C8>0,C20<=0),"적전",C20/C8-1))) -> 2.8817218 | Q20: =IF(AND(D8<=0,D20>0),"흑전",IF(AND(D8<=0,D20<=0),"적지",IF(AND(D8>0,D20<=0),"적전",D20/D8-1))) -> 1.7584376 | R20: =IF(AND(E8<=0,E20>0),"흑전",IF(AND(E8<=0,E20<=0),"적지",IF(AND(E8>0,E20<=0),"적전",E20/E8-1))) -> 2.7222462 | S20: =IF(AND(F8<=0,F20>0),"흑전",IF(AND(F8<=0,F20<=0),"적지",IF(AND(F8>0,F20<=0),"적전",F20/F8-1))) -> -0.7195122 | T20: =IF(AND(G8<=0,G20>0),"흑전",IF(AND(G8<=0,G20<=0),"적지",IF(AND(G8>0,G20<=0),"적전",G20/G8-1))) -> 0.83870968 | U20: =IF(AND(H8<=0,H20>0),"흑전",IF(AND(H8<=0,H20<=0),"적지",IF(AND(H8>0,H20<=0),"적전",H20/H8-1))) -> -0.67339982 | V20: =IF(AND(I8<=0,I20>0),"흑전",IF(AND(I8<=0,I20<=0),"적지",IF(AND(I8>0,I20<=0),"적전",I20/I8-1))) -> 0.09423884 | W20: =IF(AND(J8<=0,J20>0),"흑전",IF(AND(J8<=0,J20<=0),"적지",IF(AND(J8>0,J20<=0),"적전",J20/J8-1))) -> 4.0240964 | ... Y20: =IF(AND(L8<=0,L20>0),"흑전",IF(AND(L8<=0,L20<=0),"적지",IF(AND(L8>0,L20<=0),"적전",L20/L8-1))) -> 0.35966602
B21: 44835 | C21: 53979 | D21: 9243 | E21: 63222 | F21: 0.048 | G21: 0.073 | H21: =K21/E21 -> 0.051722502 | I21: 2600 | J21: 670 | K21: 3270 | L21: 9067 | M21: 10722 | O21: 44835 | P21: =IF(AND(C9<=0,C21>0),"흑전",IF(AND(C9<=0,C21<=0),"적지",IF(AND(C9>0,C21<=0),"적전",C21/C9-1))) -> 2.4429774 | Q21: =IF(AND(D9<=0,D21>0),"흑전",IF(AND(D9<=0,D21<=0),"적지",IF(AND(D9>0,D21<=0),"적전",D21/D9-1))) -> 2.597898 | R21: =IF(AND(E9<=0,E21>0),"흑전",IF(AND(E9<=0,E21<=0),"적지",IF(AND(E9>0,E21<=0),"적전",E21/E9-1))) -> 2.4647887 | S21: =IF(AND(F9<=0,F21>0),"흑전",IF(AND(F9<=0,F21<=0),"적지",IF(AND(F9>0,F21<=0),"적전",F21/F9-1))) -> -0.60655738 | T21: =IF(AND(G9<=0,G21>0),"흑전",IF(AND(G9<=0,G21<=0),"적지",IF(AND(G9>0,G21<=0),"적전",G21/G9-1))) -> 0.19672131 | U21: =IF(AND(H9<=0,H21>0),"흑전",IF(AND(H9<=0,H21<=0),"적지",IF(AND(H9>0,H21<=0),"적전",H21/H9-1))) -> -0.54384703 | V21: =IF(AND(I9<=0,I21>0),"흑전",IF(AND(I9<=0,I21<=0),"적지",IF(AND(I9>0,I21<=0),"적전",I21/I9-1))) -> 0.3591218 | W21: =IF(AND(J9<=0,J21>0),"흑전",IF(AND(J9<=0,J21<=0),"적지",IF(AND(J9>0,J21<=0),"적전",J21/J9-1))) -> 3.2948718 | ... Y21: =IF(AND(L9<=0,L21>0),"흑전",IF(AND(L9<=0,L21<=0),"적지",IF(AND(L9>0,L21<=0),"적전",L21/L9-1))) -> 0.12326561
B22: 44866 | C22: 65757 | D22: 14011 | E22: 79768 | F22: 0.038 | G22: 0.058 | H22: =K22/E22 -> 0.041369973 | I22: 2487 | J22: 813 | K22: 3300 | L22: 13105 | M22: 8223 | O22: 44866 | P22: =IF(AND(C10<=0,C22>0),"흑전",IF(AND(C10<=0,C22<=0),"적지",IF(AND(C10>0,C22<=0),"적전",C22/C10-1))) -> 2.0811077 | Q22: =IF(AND(D10<=0,D22>0),"흑전",IF(AND(D10<=0,D22<=0),"적지",IF(AND(D10>0,D22<=0),"적전",D22/D10-1))) -> 4.5335703 | R22: =IF(AND(E10<=0,E22>0),"흑전",IF(AND(E10<=0,E22<=0),"적지",IF(AND(E10>0,E22<=0),"적전",E22/E10-1))) -> 2.341208 | S22: =IF(AND(F10<=0,F22>0),"흑전",IF(AND(F10<=0,F22<=0),"적지",IF(AND(F10>0,F22<=0),"적전",F22/F10-1))) -> -0.50649351 | T22: =IF(AND(G10<=0,G22>0),"흑전",IF(AND(G10<=0,G22<=0),"적지",IF(AND(G10>0,G22<=0),"적전",G22/G10-1))) -> -0.275 | U22: =IF(AND(H10<=0,H22>0),"흑전",IF(AND(H10<=0,H22<=0),"적지",IF(AND(H10>0,H22<=0),"적전",H22/H10-1))) -> -0.46641451 | V22: =IF(AND(I10<=0,I22>0),"흑전",IF(AND(I10<=0,I22<=0),"적지",IF(AND(I10>0,I22<=0),"적전",I22/I10-1))) -> 0.50910194 | W22: =IF(AND(J10<=0,J22>0),"흑전",IF(AND(J10<=0,J22<=0),"적지",IF(AND(J10>0,J22<=0),"적전",J22/J10-1))) -> 2.9852941 | ... Y22: =IF(AND(L10<=0,L22>0),"흑전",IF(AND(L10<=0,L22<=0),"적지",IF(AND(L10>0,L22<=0),"적전",L22/L10-1))) -> 0.81988613
B23: 44896 | C23: 64447 | D23: 8667 | E23: 73114 | F23: 0.022 | G23: 0.077 | H23: =K23/E23 -> 0.02851711 | I23: 1420 | J23: 664 | K23: 2085 | L23: 13184 | M23: 8883 | O23: 44896 | P23: =IF(AND(C11<=0,C23>0),"흑전",IF(AND(C11<=0,C23<=0),"적지",IF(AND(C11>0,C23<=0),"적전",C23/C11-1))) -> 1.5140238 | Q23: =IF(AND(D11<=0,D23>0),"흑전",IF(AND(D11<=0,D23<=0),"적지",IF(AND(D11>0,D23<=0),"적전",D23/D11-1))) -> 2.9359673 | R23: =IF(AND(E11<=0,E23>0),"흑전",IF(AND(E11<=0,E23<=0),"적지",IF(AND(E11>0,E23<=0),"적전",E23/E11-1))) -> 1.6265043 | S23: =IF(AND(F11<=0,F23>0),"흑전",IF(AND(F11<=0,F23<=0),"적지",IF(AND(F11>0,F23<=0),"적전",F23/F11-1))) -> -0.9009009 | T23: =IF(AND(G11<=0,G23>0),"흑전",IF(AND(G11<=0,G23<=0),"적지",IF(AND(G11>0,G23<=0),"적전",G23/G11-1))) -> -0.18947368 | U23: =IF(AND(H11<=0,H23>0),"흑전",IF(AND(H11<=0,H23<=0),"적지",IF(AND(H11>0,H23<=0),"적전",H23/H11-1))) -> -0.865498 | V23: =IF(AND(I11<=0,I23>0),"흑전",IF(AND(I11<=0,I23<=0),"적지",IF(AND(I11>0,I23<=0),"적전",I23/I11-1))) -> -0.75061468 | W23: =IF(AND(J11<=0,J23>0),"흑전",IF(AND(J11<=0,J23<=0),"적지",IF(AND(J11>0,J23<=0),"적전",J23/J11-1))) -> 2.1923077 | ... Y23: =IF(AND(L11<=0,L23>0),"흑전",IF(AND(L11<=0,L23<=0),"적지",IF(AND(L11>0,L23<=0),"적전",L23/L11-1))) -> 1.638383
B24: 44927 | C24: 67226.089 | D24: 6719.7984 | E24: 73945.887 | F24: 0.086079926 | G24: 0.10501855 | H24: =K24/E24 -> 0.087800965 | I24: 5786.8168 | J24: 705.70347 | K24: 6492.5202 | L24: 10633 | M24: 6093 | O24: 44927 | P24: =IF(AND(C12<=0,C24>0),"흑전",IF(AND(C12<=0,C24<=0),"적지",IF(AND(C12>0,C24<=0),"적전",C24/C12-1))) -> 0.80982875 | Q24: =IF(AND(D12<=0,D24>0),"흑전",IF(AND(D12<=0,D24<=0),"적지",IF(AND(D12>0,D24<=0),"적전",D24/D12-1))) -> 0.8415452 | R24: =IF(AND(E12<=0,E24>0),"흑전",IF(AND(E12<=0,E24<=0),"적지",IF(AND(E12>0,E24<=0),"적전",E24/E12-1))) -> 0.81262134 | S24: =IF(AND(F12<=0,F24>0),"흑전",IF(AND(F12<=0,F24<=0),"적지",IF(AND(F12>0,F24<=0),"적전",F24/F12-1))) -> 3.7822181 | T24: =IF(AND(G12<=0,G24>0),"흑전",IF(AND(G12<=0,G24<=0),"적지",IF(AND(G12>0,G24<=0),"적전",G24/G12-1))) -> 0.32934871 | U24: =IF(AND(H12<=0,H24>0),"흑전",IF(AND(H12<=0,H24<=0),"적지",IF(AND(H12>0,H24<=0),"적전",H24/H12-1))) -> 2.8104685 | V24: =IF(AND(I12<=0,I24>0),"흑전",IF(AND(I12<=0,I24<=0),"적지",IF(AND(I12>0,I24<=0),"적전",I24/I12-1))) -> 7.902795 | W24: =IF(AND(J12<=0,J24>0),"흑전",IF(AND(J12<=0,J24<=0),"적지",IF(AND(J12>0,J24<=0),"적전",J24/J12-1))) -> 1.4334603 | ... Y24: =IF(AND(L12<=0,L24>0),"흑전",IF(AND(L12<=0,L24<=0),"적지",IF(AND(L12>0,L24<=0),"적전",L24/L12-1))) -> 1.0420588
B25: 44958 | C25: 43470.983 | D25: 6868.7729 | E25: 50339.756 | F25: 0.075429352 | G25: 0.068715487 | H25: =K25/E25 -> 0.074513256 | I25: 3278.9881 | J25: 471.99107 | K25: 3750.9791 | L25: 8656 | M25: 5853 | O25: 44958 | P25: =IF(AND(C13<=0,C25>0),"흑전",IF(AND(C13<=0,C25<=0),"적지",IF(AND(C13>0,C25<=0),"적전",C25/C13-1))) -> 0.091276089 | Q25: =IF(AND(D13<=0,D25>0),"흑전",IF(AND(D13<=0,D25<=0),"적지",IF(AND(D13>0,D25<=0),"적전",D25/D13-1))) -> 0.97208523 | R25: =IF(AND(E13<=0,E25>0),"흑전",IF(AND(E13<=0,E25<=0),"적지",IF(AND(E13>0,E25<=0),"적전",E25/E13-1))) -> 0.16209788 | S25: =IF(AND(F13<=0,F25>0),"흑전",IF(AND(F13<=0,F25<=0),"적지",IF(AND(F13>0,F25<=0),"적전",F25/F13-1))) -> 0.30050606 | T25: =IF(AND(G13<=0,G25>0),"흑전",IF(AND(G13<=0,G25<=0),"적지",IF(AND(G13>0,G25<=0),"적전",G25/G13-1))) -> -0.19158251 | U25: =IF(AND(H13<=0,H25>0),"흑전",IF(AND(H13<=0,H25<=0),"적지",IF(AND(H13>0,H25<=0),"적전",H25/H13-1))) -> 0.24336103 | V25: =IF(AND(I13<=0,I25>0),"흑전",IF(AND(I13<=0,I25<=0),"적지",IF(AND(I13>0,I25<=0),"적전",I25/I13-1))) -> 0.42502741 | W25: =IF(AND(J13<=0,J25>0),"흑전",IF(AND(J13<=0,J25<=0),"적지",IF(AND(J13>0,J25<=0),"적전",J25/J13-1))) -> 0.59996974 | ... Y25: =IF(AND(L13<=0,L25>0),"흑전",IF(AND(L13<=0,L25<=0),"적지",IF(AND(L13>0,L25<=0),"적전",L25/L13-1))) -> 0.84209406
B26: 44986 | C26: 96405.946 | D26: 8269.6836 | E26: 104675.63 | F26: 0.056142117 | G26: 0.084810253 | H26: =K26/E26 -> 0.058406984 | I26: 5412.4339 | J26: 701.35395 | K26: 6113.7878 | L26: 13401 | M26: 5734 | O26: 44986 | P26: =IF(AND(C14<=0,C26>0),"흑전",IF(AND(C14<=0,C26<=0),"적지",IF(AND(C14>0,C26<=0),"적전",C26/C14-1))) -> 2.3978059 | Q26: =IF(AND(D14<=0,D26>0),"흑전",IF(AND(D14<=0,D26<=0),"적지",IF(AND(D14>0,D26<=0),"적전",D26/D14-1))) -> 1.6169885 | R26: =IF(AND(E14<=0,E26>0),"흑전",IF(AND(E14<=0,E26<=0),"적지",IF(AND(E14>0,E26<=0),"적전",E26/E14-1))) -> 2.3196635 | S26: =IF(AND(F14<=0,F26>0),"흑전",IF(AND(F14<=0,F26<=0),"적지",IF(AND(F14>0,F26<=0),"적전",F26/F14-1))) -> -0.81652903 | T26: =IF(AND(G14<=0,G26>0),"흑전",IF(AND(G14<=0,G26<=0),"적지",IF(AND(G14>0,G26<=0),"적전",G26/G14-1))) -> 3.0385835 | U26: =IF(AND(H14<=0,H26>0),"흑전",IF(AND(H14<=0,H26<=0),"적지",IF(AND(H14>0,H26<=0),"적전",H26/H14-1))) -> -0.78959339 | V26: =IF(AND(I14<=0,I26>0),"흑전",IF(AND(I14<=0,I26<=0),"적지",IF(AND(I14>0,I26<=0),"적전",I26/I14-1))) -> -0.37687844 | W26: =IF(AND(J14<=0,J26>0),"흑전",IF(AND(J14<=0,J26<=0),"적지",IF(AND(J14>0,J26<=0),"적전",J26/J14-1))) -> 9.4679695 | ... Y26: =IF(AND(L14<=0,L26>0),"흑전",IF(AND(L14<=0,L26<=0),"적지",IF(AND(L14>0,L26<=0),"적전",L26/L14-1))) -> 2.0463742
B27: 45017 | C27: 96776.937 | D27: 9170.7027 | E27: 105947.64 | F27: 0.093978036 | G27: 0.093818578 | H27: =K27/E27 -> 0.093964233 | I27: 9094.9064 | J27: 860.38228 | K27: 9955.2887 | L27: 18717 | M27: 6923 | O27: 45017 | P27: =IF(AND(C15<=0,C27>0),"흑전",IF(AND(C15<=0,C27<=0),"적지",IF(AND(C15>0,C27<=0),"적전",C27/C15-1))) -> 2.5459819 | Q27: =IF(AND(D15<=0,D27>0),"흑전",IF(AND(D15<=0,D27<=0),"적지",IF(AND(D15>0,D27<=0),"적전",D27/D15-1))) -> 0.95913324 | R27: =IF(AND(E15<=0,E27>0),"흑전",IF(AND(E15<=0,E27<=0),"적지",IF(AND(E15>0,E27<=0),"적전",E27/E15-1))) -> 2.313556 | S27: =IF(AND(F15<=0,F27>0),"흑전",IF(AND(F15<=0,F27<=0),"적지",IF(AND(F15>0,F27<=0),"적전",F27/F15-1))) -> 0.44581593 | T27: =IF(AND(G15<=0,G27>0),"흑전",IF(AND(G15<=0,G27<=0),"적지",IF(AND(G15>0,G27<=0),"적전",G27/G15-1))) -> 0.23445497 | U27: =IF(AND(H15<=0,H27>0),"흑전",IF(AND(H15<=0,H27<=0),"적지",IF(AND(H15>0,H27<=0),"적전",H27/H15-1))) -> 0.41384112 | V27: =IF(AND(I15<=0,I27>0),"흑전",IF(AND(I15<=0,I27<=0),"적지",IF(AND(I15>0,I27<=0),"적전",I27/I15-1))) -> 4.1412699 | W27: =IF(AND(J15<=0,J27>0),"흑전",IF(AND(J15<=0,J27<=0),"적지",IF(AND(J15>0,J27<=0),"적전",J27/J15-1))) -> 1.4236121 | ... Z27: =IF(AND(M15<=0,M27>0),"흑전",IF(AND(M15<=0,M27<=0),"적지",IF(AND(M15>0,M27<=0),"적전",M27/M15-1))) -> -0.2728705
B28: 45047 | C28: 113704.5 | D28: 9712.9596 | E28: 123417.46 | F28: 0.093988286 | G28: 0.075425061 | H28: =K28/E28 -> 0.09252736 | I28: 10686.891 | J28: 732.60056 | K28: 11419.492 | L28: 21866 | M28: 7697 | O28: 45047 | P28: =IF(AND(C16<=0,C28>0),"흑전",IF(AND(C16<=0,C28<=0),"적지",IF(AND(C16>0,C28<=0),"적전",C28/C16-1))) -> 3.005231 | Q28: =IF(AND(D16<=0,D28>0),"흑전",IF(AND(D16<=0,D28<=0),"적지",IF(AND(D16>0,D28<=0),"적전",D28/D16-1))) -> 1.1613172 | R28: =IF(AND(E16<=0,E28>0),"흑전",IF(AND(E16<=0,E28<=0),"적지",IF(AND(E16>0,E28<=0),"적전",E28/E16-1))) -> 2.7531158 | S28: =IF(AND(F16<=0,F28>0),"흑전",IF(AND(F16<=0,F28<=0),"적지",IF(AND(F16>0,F28<=0),"적전",F28/F16-1))) -> -0.26571651 | T28: =IF(AND(G16<=0,G28>0),"흑전",IF(AND(G16<=0,G28<=0),"적지",IF(AND(G16>0,G28<=0),"적전",G28/G16-1))) -> -0.19760574 | U28: =IF(AND(H16<=0,H28>0),"흑전",IF(AND(H16<=0,H28<=0),"적지",IF(AND(H16>0,H28<=0),"적전",H28/H16-1))) -> -0.2500198 | V28: =IF(AND(I16<=0,I28>0),"흑전",IF(AND(I16<=0,I28<=0),"적지",IF(AND(I16>0,I28<=0),"적전",I28/I16-1))) -> 1.9408066 | W28: =IF(AND(J16<=0,J28>0),"흑전",IF(AND(J16<=0,J28<=0),"적지",IF(AND(J16>0,J28<=0),"적전",J28/J16-1))) -> 0.72783152 | ... Z28: =IF(AND(M16<=0,M28>0),"흑전",IF(AND(M16<=0,M28<=0),"적지",IF(AND(M16>0,M28<=0),"적전",M28/M16-1))) -> -0.2975908
B29: 45078 | C29: 103788.42 | D29: 9948.3811 | E29: 113736.8 | F29: 0.090585882 | G29: 0.09016134 | H29: =K29/E29 -> 0.090548748 | I29: 9401.7654 | J29: 896.95936 | K29: 10298.725 | L29: 22251 | M29: 8827 | O29: 45078 | P29: =IF(AND(C17<=0,C29>0),"흑전",IF(AND(C17<=0,C29<=0),"적지",IF(AND(C17>0,C29<=0),"적전",C29/C17-1))) -> 2.8558687 | Q29: =IF(AND(D17<=0,D29>0),"흑전",IF(AND(D17<=0,D29<=0),"적지",IF(AND(D17>0,D29<=0),"적전",D29/D17-1))) -> 0.72296174 | R29: =IF(AND(E17<=0,E29>0),"흑전",IF(AND(E17<=0,E29<=0),"적지",IF(AND(E17>0,E29<=0),"적전",E29/E17-1))) -> 2.4791471 | S29: =IF(AND(F17<=0,F29>0),"흑전",IF(AND(F17<=0,F29<=0),"적지",IF(AND(F17>0,F29<=0),"적전",F29/F17-1))) -> -0.56026271 | T29: =IF(AND(G17<=0,G29>0),"흑전",IF(AND(G17<=0,G29<=0),"적지",IF(AND(G17>0,G29<=0),"적전",G29/G17-1))) -> 0.0017926629 | U29: =IF(AND(H17<=0,H29>0),"흑전",IF(AND(H17<=0,H29<=0),"적지",IF(AND(H17>0,H29<=0),"적전",H29/H17-1))) -> -0.51088415 | V29: =IF(AND(I17<=0,I29>0),"흑전",IF(AND(I17<=0,I29<=0),"적지",IF(AND(I17>0,I29<=0),"적전",I29/I17-1))) -> 0.69952376 | W29: =IF(AND(J17<=0,J29>0),"흑전",IF(AND(J17<=0,J29<=0),"적지",IF(AND(J17>0,J29<=0),"적전",J29/J17-1))) -> 0.72492185 | ... Z29: =IF(AND(M17<=0,M29>0),"흑전",IF(AND(M17<=0,M29<=0),"적지",IF(AND(M17>0,M29<=0),"적전",M29/M17-1))) -> -0.16426813
B30: 45108 | C30: 130283.58 | D30: 28272.883 | E30: 158556.46 | F30: 0.13439015 | G30: 0.091307677 | H30: =K30/E30 -> 0.12670793 | I30: 17508.83 | J30: 2581.5313 | K30: 20090.362 | L30: 27005 | M30: 9686 | O30: 45108 | P30: =IF(AND(C18<=0,C30>0),"흑전",IF(AND(C18<=0,C30<=0),"적지",IF(AND(C18>0,C30<=0),"적전",C30/C18-1))) -> 4.2967264 | Q30: =IF(AND(D18<=0,D30>0),"흑전",IF(AND(D18<=0,D30<=0),"적지",IF(AND(D18>0,D30<=0),"적전",D30/D18-1))) -> 3.359063 | R30: =IF(AND(E18<=0,E30>0),"흑전",IF(AND(E18<=0,E30<=0),"적지",IF(AND(E18>0,E30<=0),"적전",E30/E18-1))) -> 4.1009028 | S30: =IF(AND(F18<=0,F30>0),"흑전",IF(AND(F18<=0,F30<=0),"적지",IF(AND(F18>0,F30<=0),"적전",F30/F18-1))) -> 0.24435327 | T30: =IF(AND(G18<=0,G30>0),"흑전",IF(AND(G18<=0,G30<=0),"적지",IF(AND(G18>0,G30<=0),"적전",G30/G18-1))) -> 0.0033810658 | U30: =IF(AND(H18<=0,H30>0),"흑전",IF(AND(H18<=0,H30<=0),"적지",IF(AND(H18>0,H30<=0),"적전",H30/H18-1))) -> 0.20778576 | V30: =IF(AND(I18<=0,I30>0),"흑전",IF(AND(I18<=0,I30<=0),"적지",IF(AND(I18>0,I30<=0),"적전",I30/I18-1))) -> 5.5625301 | W30: =IF(AND(J18<=0,J30>0),"흑전",IF(AND(J18<=0,J30<=0),"적지",IF(AND(J18>0,J30<=0),"적전",J30/J18-1))) -> 3.3533411 | ... Z30: =IF(AND(M18<=0,M30>0),"흑전",IF(AND(M18<=0,M30<=0),"적지",IF(AND(M18>0,M30<=0),"적전",M30/M18-1))) -> -0.13825623
B31: 45161 | C31: 132750.12 | D31: 28189.214 | E31: 160939.33 | F31: 0.11981313 | G31: 0.070964043 | H31: =K31/E31 -> 0.11125701 | I31: 15905.208 | J31: 2000.4206 | K31: 17905.628 | L31: 28718 | M31: 10541 | O31: 45161 | P31: =IF(AND(C19<=0,C31>0),"흑전",IF(AND(C19<=0,C31<=0),"적지",IF(AND(C19>0,C31<=0),"적전",C31/C19-1))) -> 2.0996105 | Q31: =IF(AND(D19<=0,D31>0),"흑전",IF(AND(D19<=0,D31<=0),"적지",IF(AND(D19>0,D31<=0),"적전",D31/D19-1))) -> 2.3474901 | R31: =IF(AND(E19<=0,E31>0),"흑전",IF(AND(E19<=0,E31<=0),"적지",IF(AND(E19>0,E31<=0),"적전",E31/E19-1))) -> 2.1402796 | S31: =IF(AND(F19<=0,F31>0),"흑전",IF(AND(F19<=0,F31<=0),"적지",IF(AND(F19>0,F31<=0),"적전",F31/F19-1))) -> 0.53606582 | T31: =IF(AND(G19<=0,G31>0),"흑전",IF(AND(G19<=0,G31<=0),"적지",IF(AND(G19>0,G31<=0),"적전",G31/G19-1))) -> -0.041026448 | U31: =IF(AND(H19<=0,H31>0),"흑전",IF(AND(H19<=0,H31<=0),"적지",IF(AND(H19>0,H31<=0),"적전",H31/H19-1))) -> 0.44206413 | V31: =IF(AND(I19<=0,I31>0),"흑전",IF(AND(I19<=0,I31<=0),"적지",IF(AND(I19>0,I31<=0),"적전",I31/I19-1))) -> 3.7749047 | W31: =IF(AND(J19<=0,J31>0),"흑전",IF(AND(J19<=0,J31<=0),"적지",IF(AND(J19>0,J31<=0),"적전",J31/J19-1))) -> 2.210948 | ... Z31: =IF(AND(M19<=0,M31>0),"흑전",IF(AND(M19<=0,M31<=0),"적지",IF(AND(M19>0,M31<=0),"적전",M31/M19-1))) -> -0.11023888
B32: 45199 | C32: 103753.27 | D32: 18082.588 | E32: 121835.86 | F32: 0.12667088 | G32: 0.065509854 | H32: =K32/E32 -> 0.11759351 | I32: 13142.519 | J32: 1184.5877 | K32: 14327.106 | L32: 28165 | M32: 7912 | O32: 45199 | P32: =IF(AND(C20<=0,C32>0),"흑전",IF(AND(C20<=0,C32<=0),"적지",IF(AND(C20>0,C32<=0),"적전",C32/C20-1))) -> 0.67714585 | Q32: =IF(AND(D20<=0,D32>0),"흑전",IF(AND(D20<=0,D32<=0),"적지",IF(AND(D20>0,D32<=0),"적전",D32/D20-1))) -> 1.4859209 | R32: =IF(AND(E20<=0,E32>0),"흑전",IF(AND(E20<=0,E32<=0),"적지",IF(AND(E20>0,E32<=0),"적전",E32/E20-1))) -> 0.7622382 | S32: =IF(AND(F20<=0,F32>0),"흑전",IF(AND(F20<=0,F32<=0),"적지",IF(AND(F20>0,F32<=0),"적전",F32/F20-1))) -> 1.7537148 | T32: =IF(AND(G20<=0,G32>0),"흑전",IF(AND(G20<=0,G32<=0),"적지",IF(AND(G20>0,G32<=0),"적전",G32/G20-1))) -> 0.14929569 | U32: =IF(AND(H20<=0,H32>0),"흑전",IF(AND(H20<=0,H32<=0),"적지",IF(AND(H20>0,H32<=0),"적전",H32/H20-1))) -> 1.4741516 | V32: =IF(AND(I20<=0,I32>0),"흑전",IF(AND(I20<=0,I32<=0),"적지",IF(AND(I20>0,I32<=0),"적전",I32/I20-1))) -> 3.5824681 | W32: =IF(AND(J20<=0,J32>0),"흑전",IF(AND(J20<=0,J32<=0),"적지",IF(AND(J20>0,J32<=0),"적전",J32/J20-1))) -> 1.840738 | ... Z32: =IF(AND(M20<=0,M32>0),"흑전",IF(AND(M20<=0,M32<=0),"적지",IF(AND(M20>0,M32<=0),"적전",M32/M20-1))) -> -0.075376884
B33: 45230 | C33: 143448 | D33: 13137.548 | E33: 156585.55 | F33: 0.12907566 | G33: 0.097443815 | H33: =K33/E33 -> 0.12642174 | I33: 18515.645 | J33: 1280.1728 | K33: 19795.818 | L33: 30582 | M33: 8836 | O33: 45230 | P33: =IF(AND(C21<=0,C33>0),"흑전",IF(AND(C21<=0,C33<=0),"적지",IF(AND(C21>0,C33<=0),"적전",C33/C21-1))) -> 1.6574779 | Q33: =IF(AND(D21<=0,D33>0),"흑전",IF(AND(D21<=0,D33<=0),"적지",IF(AND(D21>0,D33<=0),"적전",D33/D21-1))) -> 0.42135111 | R33: =IF(AND(E21<=0,E33>0),"흑전",IF(AND(E21<=0,E33<=0),"적지",IF(AND(E21>0,E33<=0),"적전",E33/E21-1))) -> 1.4767573 | S33: =IF(AND(F21<=0,F33>0),"흑전",IF(AND(F21<=0,F33<=0),"적지",IF(AND(F21>0,F33<=0),"적전",F33/F21-1))) -> 1.6890762 | T33: =IF(AND(G21<=0,G33>0),"흑전",IF(AND(G21<=0,G33<=0),"적지",IF(AND(G21>0,G33<=0),"적전",G33/G21-1))) -> 0.33484678 | U33: =IF(AND(H21<=0,H33>0),"흑전",IF(AND(H21<=0,H33<=0),"적지",IF(AND(H21>0,H33<=0),"적전",H33/H21-1))) -> 1.444231 | V33: =IF(AND(I21<=0,I33>0),"흑전",IF(AND(I21<=0,I33<=0),"적지",IF(AND(I21>0,I33<=0),"적전",I33/I21-1))) -> 6.1214019 | W33: =IF(AND(J21<=0,J33>0),"흑전",IF(AND(J21<=0,J33<=0),"적지",IF(AND(J21>0,J33<=0),"적전",J33/J21-1))) -> 0.9107057 | ... Z33: =IF(AND(M21<=0,M33>0),"흑전",IF(AND(M21<=0,M33<=0),"적지",IF(AND(M21>0,M33<=0),"적전",M33/M21-1))) -> -0.17590002
B34: 45260 | C34: 116903.92 | D34: 19435.015 | E34: 136338.93 | F34: 0.1374552 | G34: 0.095720365 | H34: =K34/E34 -> 0.13150593 | I34: 16069.051 | J34: 1860.3267 | K34: 17929.378 | L34: 28547 | M34: 6634 | O34: 45260 | P34: =IF(AND(C22<=0,C34>0),"흑전",IF(AND(C22<=0,C34<=0),"적지",IF(AND(C22>0,C34<=0),"적전",C34/C22-1))) -> 0.77781708 | Q34: =IF(AND(D22<=0,D34>0),"흑전",IF(AND(D22<=0,D34<=0),"적지",IF(AND(D22>0,D34<=0),"적전",D34/D22-1))) -> 0.38712545 | R34: =IF(AND(E22<=0,E34>0),"흑전",IF(AND(E22<=0,E34<=0),"적지",IF(AND(E22>0,E34<=0),"적전",E34/E22-1))) -> 0.70919332 | S34: =IF(AND(F22<=0,F34>0),"흑전",IF(AND(F22<=0,F34<=0),"적지",IF(AND(F22>0,F34<=0),"적전",F34/F22-1))) -> 2.617242 | T34: =IF(AND(G22<=0,G34>0),"흑전",IF(AND(G22<=0,G34<=0),"적지",IF(AND(G22>0,G34<=0),"적전",G34/G22-1))) -> 0.65035111 | U34: =IF(AND(H22<=0,H34>0),"흑전",IF(AND(H22<=0,H34<=0),"적지",IF(AND(H22>0,H34<=0),"적전",H34/H22-1))) -> 2.1787772 | V34: =IF(AND(I22<=0,I34>0),"흑전",IF(AND(I22<=0,I34<=0),"적지",IF(AND(I22>0,I34<=0),"적전",I34/I22-1))) -> 5.4612187 | W34: =IF(AND(J22<=0,J34>0),"흑전",IF(AND(J22<=0,J34<=0),"적지",IF(AND(J22>0,J34<=0),"적전",J34/J22-1))) -> 1.2882247 | ... Z34: =IF(AND(M22<=0,M34>0),"흑전",IF(AND(M22<=0,M34<=0),"적지",IF(AND(M22>0,M34<=0),"적전",M34/M22-1))) -> -0.19323848
B35: 45291 | C35: 126239.84 | D35: 12149.46 | E35: 138389.3 | F35: 0.1055201 | G35: 0.083857541 | H35: =K35/E35 -> 0.1036183 | I35: 13320.84 | J35: 1018.8238 | K35: 14339.664 | L35: 28328 | M35: 6977 | O35: 45291 | P35: =IF(AND(C23<=0,C35>0),"흑전",IF(AND(C23<=0,C35<=0),"적지",IF(AND(C23>0,C35<=0),"적전",C35/C23-1))) -> 0.95881639 | Q35: =IF(AND(D23<=0,D35>0),"흑전",IF(AND(D23<=0,D35<=0),"적지",IF(AND(D23>0,D35<=0),"적전",D35/D23-1))) -> 0.4018068 | R35: =IF(AND(E23<=0,E35>0),"흑전",IF(AND(E23<=0,E35<=0),"적지",IF(AND(E23>0,E35<=0),"적전",E35/E23-1))) -> 0.89278797 | S35: =IF(AND(F23<=0,F35>0),"흑전",IF(AND(F23<=0,F35<=0),"적지",IF(AND(F23>0,F35<=0),"적전",F35/F23-1))) -> 3.796368 | T35: =IF(AND(G23<=0,G35>0),"흑전",IF(AND(G23<=0,G35<=0),"적지",IF(AND(G23>0,G35<=0),"적전",G35/G23-1))) -> 0.089058978 | U35: =IF(AND(H23<=0,H35>0),"흑전",IF(AND(H23<=0,H35<=0),"적지",IF(AND(H23>0,H35<=0),"적전",H35/H23-1))) -> 2.6335483 | V35: =IF(AND(I23<=0,I35>0),"흑전",IF(AND(I23<=0,I35<=0),"적지",IF(AND(I23>0,I35<=0),"적전",I35/I23-1))) -> 8.3808732 | W35: =IF(AND(J23<=0,J35>0),"흑전",IF(AND(J23<=0,J35<=0),"적지",IF(AND(J23>0,J35<=0),"적전",J35/J23-1))) -> 0.5343732 | ... Z35: =IF(AND(M23<=0,M35>0),"흑전",IF(AND(M23<=0,M35<=0),"적지",IF(AND(M23>0,M35<=0),"적전",M35/M23-1))) -> -0.21456715
B36: 45322 | C36: 120821.45 | D36: 11036.752 | E36: 131858.21 | F36: 0.18826791 | G36: 0.1025141 | H36: =K36/E36 -> 0.18109018 | I36: 22746.803 | J36: 1131.4227 | K36: 23878.226 | L36: 26245 | M36: 5141 | O36: 45322 | P36: =IF(AND(C24<=0,C36>0),"흑전",IF(AND(C24<=0,C36<=0),"적지",IF(AND(C24>0,C36<=0),"적전",C36/C24-1))) -> 0.79724055 | Q36: =IF(AND(D24<=0,D36>0),"흑전",IF(AND(D24<=0,D36<=0),"적지",IF(AND(D24>0,D36<=0),"적전",D36/D24-1))) -> 0.64242311 | R36: =IF(AND(E24<=0,E36>0),"흑전",IF(AND(E24<=0,E36<=0),"적지",IF(AND(E24>0,E36<=0),"적전",E36/E24-1))) -> 0.78317158 | S36: =IF(AND(F24<=0,F36>0),"흑전",IF(AND(F24<=0,F36<=0),"적지",IF(AND(F24>0,F36<=0),"적전",F36/F24-1))) -> 1.1871291 | T36: =IF(AND(G24<=0,G36>0),"흑전",IF(AND(G24<=0,G36<=0),"적지",IF(AND(G24>0,G36<=0),"적전",G36/G24-1))) -> -0.023847712 | U36: =IF(AND(H24<=0,H36>0),"흑전",IF(AND(H24<=0,H36<=0),"적지",IF(AND(H24>0,H36<=0),"적전",H36/H24-1))) -> 1.0625078 | V36: =IF(AND(I24<=0,I36>0),"흑전",IF(AND(I24<=0,I36<=0),"적지",IF(AND(I24>0,I36<=0),"적전",I36/I24-1))) -> 2.9307972 | W36: =IF(AND(J24<=0,J36>0),"흑전",IF(AND(J24<=0,J36<=0),"적지",IF(AND(J24>0,J36<=0),"적전",J36/J24-1))) -> 0.60325508 | ... Z36: =IF(AND(M24<=0,M36>0),"흑전",IF(AND(M24<=0,M36<=0),"적지",IF(AND(M24>0,M36<=0),"적전",M36/M24-1))) -> -0.15624487
B37: 45351 | C37: 105444.95 | D37: 12213.009 | E37: 117657.96 | F37: 0.21600179 | G37: 0.095610739 | H37: =K37/E37 -> 0.20350508 | I37: 22776.297 | J37: 1167.6949 | K37: 23943.991 | L37: 25328 | M37: 6128 | O37: 45351 | P37: =IF(AND(C25<=0,C37>0),"흑전",IF(AND(C25<=0,C37<=0),"적지",IF(AND(C25>0,C37<=0),"적전",C37/C25-1))) -> 1.4256398 | Q37: =IF(AND(D25<=0,D37>0),"흑전",IF(AND(D25<=0,D37<=0),"적지",IF(AND(D25>0,D37<=0),"적전",D37/D25-1))) -> 0.77804822 | R37: =IF(AND(E25<=0,E37>0),"흑전",IF(AND(E25<=0,E37<=0),"적지",IF(AND(E25>0,E37<=0),"적전",E37/E25-1))) -> 1.337277 | S37: =IF(AND(F25<=0,F37>0),"흑전",IF(AND(F25<=0,F37<=0),"적지",IF(AND(F25>0,F37<=0),"적전",F37/F25-1))) -> 1.8636304 | T37: =IF(AND(G25<=0,G37>0),"흑전",IF(AND(G25<=0,G37<=0),"적지",IF(AND(G25>0,G37<=0),"적전",G37/G25-1))) -> 0.39140015 | U37: =IF(AND(H25<=0,H37>0),"흑전",IF(AND(H25<=0,H37<=0),"적지",IF(AND(H25>0,H37<=0),"적전",H37/H25-1))) -> 1.7311258 | V37: =IF(AND(I25<=0,I37>0),"흑전",IF(AND(I25<=0,I37<=0),"적지",IF(AND(I25>0,I37<=0),"적전",I37/I25-1))) -> 5.9461359 | W37: =IF(AND(J25<=0,J37>0),"흑전",IF(AND(J25<=0,J37<=0),"적지",IF(AND(J25>0,J37<=0),"적전",J37/J25-1))) -> 1.4739766 | ... Z37: =IF(AND(M25<=0,M37>0),"흑전",IF(AND(M25<=0,M37<=0),"적지",IF(AND(M25>0,M37<=0),"적전",M37/M25-1))) -> 0.046984452
B38: 45382 | C38: 121940.96 | D38: 13216.175 | E38: 135157.14 | F38: 0.17335294 | G38: 0.079225481 | H38: =K38/E38 -> 0.1641488 | I38: 21138.825 | J38: 1047.0578 | K38: 22185.883 | L38: 27679 | M38: 5487 | O38: 45382 | P38: =IF(AND(C26<=0,C38>0),"흑전",IF(AND(C26<=0,C38<=0),"적지",IF(AND(C26>0,C38<=0),"적전",C38/C26-1))) -> 0.26486974 | Q38: =IF(AND(D26<=0,D38>0),"흑전",IF(AND(D26<=0,D38<=0),"적지",IF(AND(D26>0,D38<=0),"적전",D38/D26-1))) -> 0.59814763 | R38: =IF(AND(E26<=0,E38>0),"흑전",IF(AND(E26<=0,E38<=0),"적지",IF(AND(E26>0,E38<=0),"적전",E38/E26-1))) -> 0.29119968 | S38: =IF(AND(F26<=0,F38>0),"흑전",IF(AND(F26<=0,F38<=0),"적지",IF(AND(F26>0,F38<=0),"적전",F38/F26-1))) -> 2.0877522 | T38: =IF(AND(G26<=0,G38>0),"흑전",IF(AND(G26<=0,G38<=0),"적지",IF(AND(G26>0,G38<=0),"적전",G38/G26-1))) -> -0.065850191 | U38: =IF(AND(H26<=0,H38>0),"흑전",IF(AND(H26<=0,H38<=0),"적지",IF(AND(H26>0,H38<=0),"적전",H38/H26-1))) -> 1.8104311 | V38: =IF(AND(I26<=0,I38>0),"흑전",IF(AND(I26<=0,I38<=0),"적지",IF(AND(I26>0,I38<=0),"적전",I38/I26-1))) -> 2.9056043 | W38: =IF(AND(J26<=0,J38>0),"흑전",IF(AND(J26<=0,J38<=0),"적지",IF(AND(J26>0,J38<=0),"적전",J38/J26-1))) -> 0.4929093 | ... Z38: =IF(AND(M26<=0,M38>0),"흑전",IF(AND(M26<=0,M38<=0),"적지",IF(AND(M26>0,M38<=0),"적전",M38/M26-1))) -> -0.043076386
... B44: 45565 | C44: 129411.85 | D44: 14023.296 | E44: 143435.15 | F44: 0.20983203 | G44: 0.090400426 | H44: =K44/E44 -> 0.1981555 | I44: 27154.752 | J44: 1267.7119 | K44: 28422.464 | L44: 35764 | M44: 6814 | O44: 45565 | P44: =IF(AND(C32<=0,C44>0),"흑전",IF(AND(C32<=0,C44<=0),"적지",IF(AND(C32>0,C44<=0),"적전",C44/C32-1))) -> 0.24730382 | Q44: =IF(AND(D32<=0,D44>0),"흑전",IF(AND(D32<=0,D44<=0),"적지",IF(AND(D32>0,D44<=0),"적전",D44/D32-1))) -> -0.22448625 | R44: =IF(AND(E32<=0,E44>0),"흑전",IF(AND(E32<=0,E44<=0),"적지",IF(AND(E32>0,E44<=0),"적전",E44/E32-1))) -> 0.17728186 | S44: =IF(AND(F32<=0,F44>0),"흑전",IF(AND(F32<=0,F44<=0),"적지",IF(AND(F32>0,F44<=0),"적전",F44/F32-1))) -> 0.65651355 | T44: =IF(AND(G32<=0,G44>0),"흑전",IF(AND(G32<=0,G44<=0),"적지",IF(AND(G32>0,G44<=0),"적전",G44/G32-1))) -> 0.37995157 | U44: =IF(AND(H32<=0,H44>0),"흑전",IF(AND(H32<=0,H44<=0),"적지",IF(AND(H32>0,H44<=0),"적전",H44/H32-1))) -> 0.6850888 | V44: =IF(AND(I32<=0,I44>0),"흑전",IF(AND(I32<=0,I44<=0),"적지",IF(AND(I32>0,I44<=0),"적전",I44/I32-1))) -> 1.0661757 | W44: =IF(AND(J32<=0,J44>0),"흑전",IF(AND(J32<=0,J44<=0),"적지",IF(AND(J32>0,J44<=0),"적전",J44/J32-1))) -> 0.070171419 | ... Z44: =IF(AND(M32<=0,M44>0),"흑전",IF(AND(M32<=0,M44<=0),"적지",IF(AND(M32>0,M44<=0),"적전",M44/M32-1))) -> -0.13877654
B45: 45596 | C45: 137072.06 | D45: 16928.518 | E45: 154000.58 | F45: 0.16882722 | G45: 0.062543425 | H45: =K45/E45 -> 0.15714397 | I45: 23141.495 | J45: 1058.7675 | K45: 24200.263 | L45: 37312 | M45: 7699 | O45: 45596 | P45: =IF(AND(C32<=0,C45>0),"흑전",IF(AND(C32<=0,C45<=0),"적지",IF(AND(C32>0,C45<=0),"적전",C45/C32-1))) -> 0.32113479 | Q45: =IF(AND(D32<=0,D45>0),"흑전",IF(AND(D32<=0,D45<=0),"적지",IF(AND(D32>0,D45<=0),"적전",D45/D32-1))) -> -0.063822211 | R45: =IF(AND(E32<=0,E45>0),"흑전",IF(AND(E32<=0,E45<=0),"적지",IF(AND(E32>0,E45<=0),"적전",E45/E32-1))) -> 0.26400039 | S45: =IF(AND(F32<=0,F45>0),"흑전",IF(AND(F32<=0,F45<=0),"적지",IF(AND(F32>0,F45<=0),"적전",F45/F32-1))) -> 0.33280216 | T45: =IF(AND(G32<=0,G45>0),"흑전",IF(AND(G32<=0,G45<=0),"적지",IF(AND(G32>0,G45<=0),"적전",G45/G32-1))) -> -0.045282193 | U45: =IF(AND(H32<=0,H45>0),"흑전",IF(AND(H32<=0,H45<=0),"적지",IF(AND(H32>0,H45<=0),"적전",H45/H32-1))) -> 0.33633207 | V45: =IF(AND(I32<=0,I45>0),"흑전",IF(AND(I32<=0,I45<=0),"적지",IF(AND(I32>0,I45<=0),"적전",I45/I32-1))) -> 0.76081131 | W45: =IF(AND(J32<=0,J45>0),"흑전",IF(AND(J32<=0,J45<=0),"적지",IF(AND(J32>0,J45<=0),"적전",J45/J32-1))) -> -0.10621439 | X45: =IF(AND(K33<=0,K45>0),"흑전",IF(AND(K33<=0,K45<=0),"적지",IF(AND(K33>0,K45<=0),"적전",K45/K33-1))) -> 0.22249371 | Y45: =IF(AND(L32<=0,L45>0),"흑전",IF(AND(L32<=0,L45<=0),"적지",IF(AND(L32>0,L45<=0),"적전",L45/L32-1))) -> 0.32476478 | Z45: =IF(AND(M32<=0,M45>0),"흑전",IF(AND(M32<=0,M45<=0),"적지",IF(AND(M32>0,M45<=0),"적전",M45/M32-1))) -> -0.026921132
B46: 45626 | C46: 133102 | D46: 14655 | E46: 147758 | F46: 0.187 | G46: 0.083 | H46: =K46/E46 -> 0.17651159 | I46: 24862 | J46: 1219 | K46: 26081 | L46: 35812 | M46: 5562 | O46: 45626 | P46: =IF(AND(C33<=0,C46>0),"흑전",IF(AND(C33<=0,C46<=0),"적지",IF(AND(C33>0,C46<=0),"적전",C46/C33-1))) -> -0.072123696 | Q46: =IF(AND(D33<=0,D46>0),"흑전",IF(AND(D33<=0,D46<=0),"적지",IF(AND(D33>0,D46<=0),"적전",D46/D33-1))) -> 0.11550494 | R46: =IF(AND(E33<=0,E46>0),"흑전",IF(AND(E33<=0,E46<=0),"적지",IF(AND(E33>0,E46<=0),"적전",E46/E33-1))) -> -0.056375243 | S46: =IF(AND(F33<=0,F46>0),"흑전",IF(AND(F33<=0,F46<=0),"적지",IF(AND(F33>0,F46<=0),"적전",F46/F33-1))) -> 0.44876271 | T46: =IF(AND(G33<=0,G46>0),"흑전",IF(AND(G33<=0,G46<=0),"적지",IF(AND(G33>0,G46<=0),"적전",G46/G33-1))) -> -0.14822711 | U46: =IF(AND(H33<=0,H46>0),"흑전",IF(AND(H33<=0,H46<=0),"적지",IF(AND(H33>0,H46<=0),"적전",H46/H33-1))) -> 0.39621231 | V46: =IF(AND(I33<=0,I46>0),"흑전",IF(AND(I33<=0,I46<=0),"적지",IF(AND(I33>0,I46<=0),"적전",I46/I33-1))) -> 0.34275635 | W46: =IF(AND(J33<=0,J46>0),"흑전",IF(AND(J33<=0,J46<=0),"적지",IF(AND(J33>0,J46<=0),"적전",J46/J33-1))) -> -0.047784815 | X46: =IF(AND(K34<=0,K46>0),"흑전",IF(AND(K34<=0,K46<=0),"적지",IF(AND(K34>0,K46<=0),"적전",K46/K34-1))) -> 0.45465172 | Y46: =IF(AND(L33<=0,L46>0),"흑전",IF(AND(L33<=0,L46<=0),"적지",IF(AND(L33>0,L46<=0),"적전",L46/L33-1))) -> 0.17101563 | Z46: =IF(AND(M33<=0,M46>0),"흑전",IF(AND(M33<=0,M46<=0),"적지",IF(AND(M33>0,M46<=0),"적전",M46/M33-1))) -> -0.37052965
...

Sheet 커버리지 타임라인
C3: 드롭액 | D3: y-y | E3: 테이블 | F3: 머신 | G3: 인당드롭액 | H3: 전체 고객수 | I3: 매출액 | J3: y-y | K3: 테이블 | L3: 머신 | M3: 홀드율 | N3: 테이블 | O3: 머신
B4: =+DreamtowerCasino!B9 -> 44470 | C4: =+DreamtowerCasino!E9/1000 -> 18.247 | D4: =+DreamtowerCasino!R9 -> 0 | E4: =+DreamtowerCasino!C9/1000 -> 15.678 | F4: =+DreamtowerCasino!D9/1000 -> 2.569 | G4: =+C4/H4*1000 -> 2.2605302 | H4: =+DreamtowerCasino!L9 -> 8072 | I4: =+DreamtowerCasino!K9/1000 -> 2.069 | J4: =+DreamtowerCasino!X9 -> 0 | K4: =+DreamtowerCasino!I9/1000 -> 1.913 | L4: =+DreamtowerCasino!J9/1000 -> 0.156 | M4: =+DreamtowerCasino!H9 -> 0.1133885 | N4: =+DreamtowerCasino!F9 -> 0.122 | O4: =+DreamtowerCasino!G9 -> 0.061
B5: =+DreamtowerCasino!B10 -> 44501 | C5: =+DreamtowerCasino!E10/1000 -> 23.874 | D5: =+DreamtowerCasino!R10 -> 0 | E5: =+DreamtowerCasino!C10/1000 -> 21.342 | F5: =+DreamtowerCasino!D10/1000 -> 2.532 | G5: =+C5/H5*1000 -> 3.3153729 | H5: =+DreamtowerCasino!L10 -> 7201 | I5: =+DreamtowerCasino!K10/1000 -> 1.851 | J5: =+DreamtowerCasino!X10 -> 0 | K5: =+DreamtowerCasino!I10/1000 -> 1.648 | L5: =+DreamtowerCasino!J10/1000 -> 0.204 | M5: =+DreamtowerCasino!H10 -> 0.077532043 | N5: =+DreamtowerCasino!F10 -> 0.077 | O5: =+DreamtowerCasino!G10 -> 0.08
B6: =+DreamtowerCasino!B11 -> 44531 | C6: =+DreamtowerCasino!E11/1000 -> 27.837 | D6: =+DreamtowerCasino!R11 -> 0 | E6: =+DreamtowerCasino!C11/1000 -> 25.635 | F6: =+DreamtowerCasino!D11/1000 -> 2.202 | G6: =+C6/H6*1000 -> 5.5707424 | H6: =+DreamtowerCasino!L11 -> 4997 | I6: =+DreamtowerCasino!K11/1000 -> 5.902 | J6: =+DreamtowerCasino!X11 -> 0 | K6: =+DreamtowerCasino!I11/1000 -> 5.694 | L6: =+DreamtowerCasino!J11/1000 -> 0.208 | M6: =+DreamtowerCasino!H11 -> 0.21201997 | N6: =+DreamtowerCasino!F11 -> 0.222 | O6: =+DreamtowerCasino!G11 -> 0.095
B7: =+DreamtowerCasino!B12 -> 44562 | C7: =+DreamtowerCasino!E12/1000 -> 40.795 | D7: =+DreamtowerCasino!R12 -> 0 | E7: =+DreamtowerCasino!C12/1000 -> 37.145 | F7: =+DreamtowerCasino!D12/1000 -> 3.649 | G7: =+C7/H7*1000 -> 7.8346457 | H7: =+DreamtowerCasino!L12 -> 5207 | I7: =+DreamtowerCasino!K12/1000 -> 0.94 | J7: =+DreamtowerCasino!X12 -> 0 | K7: =+DreamtowerCasino!I12/1000 -> 0.65 | L7: =+DreamtowerCasino!J12/1000 -> 0.29 | M7: =+DreamtowerCasino!H12 -> 0.023042039 | N7: =+DreamtowerCasino!F12 -> 0.018 | O7: =+DreamtowerCasino!G12 -> 0.079
B8: =+DreamtowerCasino!B13 -> 44593 | C8: =+DreamtowerCasino!E13/1000 -> 43.318 | D8: =+DreamtowerCasino!R13 -> 0 | E8: =+DreamtowerCasino!C13/1000 -> 39.835 | F8: =+DreamtowerCasino!D13/1000 -> 3.483 | G8: =+C8/H8*1000 -> 9.2185571 | H8: =+DreamtowerCasino!L13 -> 4699 | I8: =+DreamtowerCasino!K13/1000 -> 2.596 | J8: =+DreamtowerCasino!X13 -> 0 | K8: =+DreamtowerCasino!I13/1000 -> 2.301 | L8: =+DreamtowerCasino!J13/1000 -> 0.295 | M8: =+DreamtowerCasino!H13 -> 0.059928898 | N8: =+DreamtowerCasino!F13 -> 0.058 | O8: =+DreamtowerCasino!G13 -> 0.085
B9: =+DreamtowerCasino!B14 -> 44621 | C9: =+DreamtowerCasino!E14/1000 -> 31.532 | D9: =+DreamtowerCasino!R14 -> 0 | E9: =+DreamtowerCasino!C14/1000 -> 28.373 | F9: =+DreamtowerCasino!D14/1000 -> 3.16 | G9: =+C9/H9*1000 -> 7.1679927 | H9: =+DreamtowerCasino!L14 -> 4399 | I9: =+DreamtowerCasino!K14/1000 -> 8.753 | J9: =+DreamtowerCasino!X14 -> 0 | K9: =+DreamtowerCasino!I14/1000 -> 8.686 | L9: =+DreamtowerCasino!J14/1000 -> 0.067 | M9: =+DreamtowerCasino!H14 -> 0.27759102 | N9: =+DreamtowerCasino!F14 -> 0.306 | O9: =+DreamtowerCasino!G14 -> 0.021
B10: =+DreamtowerCasino!B15 -> 44652 | C10: =+DreamtowerCasino!E15/1000 -> 31.974 | D10: =+DreamtowerCasino!R15 -> 0 | E10: =+DreamtowerCasino!C15/1000 -> 27.292 | F10: =+DreamtowerCasino!D15/1000 -> 4.681 | G10: =+C10/H10*1000 -> 6.3065089 | H10: =+DreamtowerCasino!L15 -> 5070 | I10: =+DreamtowerCasino!K15/1000 -> 2.125 | J10: =+DreamtowerCasino!X15 -> 0 | K10: =+DreamtowerCasino!I15/1000 -> 1.769 | L10: =+DreamtowerCasino!J15/1000 -> 0.355 | M10: =+DreamtowerCasino!H15 -> 0.066460249 | N10: =+DreamtowerCasino!F15 -> 0.065 | O10: =+DreamtowerCasino!G15 -> 0.076
B11: =+DreamtowerCasino!B16 -> 44682 | C11: =+DreamtowerCasino!E16/1000 -> 32.884 | D11: =+DreamtowerCasino!R16 -> 0 | E11: =+DreamtowerCasino!C16/1000 -> 28.389 | F11: =+DreamtowerCasino!D16/1000 -> 4.494 | G11: =+C11/H11*1000 -> 4.6043125 | H11: =+DreamtowerCasino!L16 -> 7142 | I11: =+DreamtowerCasino!K16/1000 -> 4.057 | J11: =+DreamtowerCasino!X16 -> 0 | K11: =+DreamtowerCasino!I16/1000 -> 3.634 | L11: =+DreamtowerCasino!J16/1000 -> 0.424 | M11: =+DreamtowerCasino!H16 -> 0.12337307 | N11: =+DreamtowerCasino!F16 -> 0.128 | O11: =+DreamtowerCasino!G16 -> 0.094
B12: =+DreamtowerCasino!B17 -> 44713 | C12: =+DreamtowerCasino!E17/1000 -> 32.691 | D12: =+DreamtowerCasino!R17 -> 0.33820459 | E12: =+DreamtowerCasino!C17/1000 -> 26.917 | F12: =+DreamtowerCasino!D17/1000 -> 5.774 | G12: =+C12/H12*1000 -> 4.3640368 | H12: =+DreamtowerCasino!L17 -> 7491 | I12: =+DreamtowerCasino!K17/1000 -> 6.052 | J12: =+DreamtowerCasino!X17 -> 0.9855643 | K12: =+DreamtowerCasino!I17/1000 -> 5.532 | L12: =+DreamtowerCasino!J17/1000 -> 0.52 | M12: =+DreamtowerCasino!H17 -> 0.18512741 | N12: =+DreamtowerCasino!F17 -> 0.206 | O12: =+DreamtowerCasino!G17 -> 0.09
B13: =+DreamtowerCasino!B18 -> 44743 | C13: =+DreamtowerCasino!E18/1000 -> 31.084 | D13: =+DreamtowerCasino!R18 -> -0.10086489 | E13: =+DreamtowerCasino!C18/1000 -> 24.597 | F13: =+DreamtowerCasino!D18/1000 -> 6.486 | G13: =+C13/H13*1000 -> 4.0191363 | H13: =+DreamtowerCasino!L18 -> 7734 | I13: =+DreamtowerCasino!K18/1000 -> 3.261 | J13: =+DreamtowerCasino!X18 -> 2.3688017 | K13: =+DreamtowerCasino!I18/1000 -> 2.668 | L13: =+DreamtowerCasino!J18/1000 -> 0.593 | M13: =+DreamtowerCasino!H18 -> 0.10490928 | N13: =+DreamtowerCasino!F18 -> 0.108 | O13: =+DreamtowerCasino!G18 -> 0.091
B14: =+DreamtowerCasino!B19 -> 44774 | C14: =+DreamtowerCasino!E19/1000 -> 51.25 | D14: =+DreamtowerCasino!R19 -> 0.731887 | E14: =+DreamtowerCasino!C19/1000 -> 42.828 | F14: =+DreamtowerCasino!D19/1000 -> 8.421 | G14: =+C14/H14*1000 -> 5.9200647 | H14: =+DreamtowerCasino!L19 -> 8657 | I14: =+DreamtowerCasino!K19/1000 -> 3.954 | J14: =+DreamtowerCasino!X19 -> -0.11878761 | K14: =+DreamtowerCasino!I19/1000 -> 3.331 | L14: =+DreamtowerCasino!J19/1000 -> 0.623 | M14: =+DreamtowerCasino!H19 -> 0.07715122 | N14: =+DreamtowerCasino!F19 -> 0.078 | O14: =+DreamtowerCasino!G19 -> 0.074
B15: =+DreamtowerCasino!B20 -> 44805 | C15: =+DreamtowerCasino!E20/1000 -> 69.137 | D15: =+DreamtowerCasino!R20 -> 2.7222462 | E15: =+DreamtowerCasino!C20/1000 -> 61.863 | F15: =+DreamtowerCasino!D20/1000 -> 7.274 | G15: =+C15/H15*1000 -> 8.1645017 | H15: =+DreamtowerCasino!L20 -> 8468 | I15: =+DreamtowerCasino!K20/1000 -> 3.286 | J15: =+DreamtowerCasino!X20 -> 0.21568627 | K15: =+DreamtowerCasino!I20/1000 -> 2.868 | L15: =+DreamtowerCasino!J20/1000 -> 0.417 | M15: =+DreamtowerCasino!H20 -> 0.04752882 | N15: =+DreamtowerCasino!F20 -> 0.046 | O15: =+DreamtowerCasino!G20 -> 0.057
... B56: =+DreamtowerCasino!B61 -> 46054 | C56: =+DreamtowerCasino!E61/1000 -> 172.92306 | D56: =+DreamtowerCasino!R61 -> 0.046312759 | E56: =+DreamtowerCasino!C61/1000 -> 151.46694 | F56: =+DreamtowerCasino!D61/1000 -> 21.456119 | G56: =+C56/H56*1000 -> 3.9377662 | H56: =+DreamtowerCasino!L61 -> 43914 | I56: =+DreamtowerCasino!K61/1000 -> 32.632348 | J56: =+DreamtowerCasino!X61 -> 0.44282389 | K56: =+DreamtowerCasino!I61/1000 -> 30.859031 | L56: =+DreamtowerCasino!J61/1000 -> 1.7733172 | M56: =+DreamtowerCasino!H61 -> 0.18871021 | N56: =+DreamtowerCasino!F61 -> 0.20373443 | O56: =+DreamtowerCasino!G61 -> 0.082648551
