Workbook
Name Annual_: [1]Annual!$B$25:$X$660
Name ECON_: [1]Econ!$D$62:$AX$133
Name FA_: [1]ForecastA!$B$27:$X$998
Name FQ_: [1]ForecastQ!$B$27:$AM$415
Name HA_: [1]SummarizeA!$B$15:$AR$731
Name HA__: [1]SummarizeA!$B$732:$AR$826
Name HQ_: [1]SummarizeQ!$B$15:$CN$731
Name Lan: [1]Setting!#REF!
Name Lan: [1]Setting!#REF!
Name Lan: [1]Setting!#REF!
Name Lang: [1]Setting!$AC$9
Name Parent_: [1]Setting!$AC$22
Name Quarter_: [1]Quarter!$B$25:$AG$699
Name rawA_: [1]DetailA!$B$2:$AM$2499
Name rawA__: [1]DetailA!$B$2500:$AM$2700
Name RawQQ_: [1]DetailQQ!$B$2:$DC$2499
Name RawQQ__: [1]DetailQQ!$B$2500:$DC$2700
Name RawQR_: [1]DetailQQ!$B$2:$DC$2499
Name REC_: [1]Setting!$AH$9
Name U_: [1]Setting!$AD$15
Name U_R: [1]Report1!$S$5
Name U_RR: [1]Report2!$W$22
Name U_RRR: [1]Report3!$N$22
Name Unit_: [1]Setting!$AB$16
Name Unit_R: [1]Report1!$Q$6
Name Unit_RR: [1]Report2!$U$23
Name Unit_RR_US: [1]Report2_USD!$U$23
Name Unit_RRR: [1]Report3!$L$23
Name Update_: [1]Setting!$AK$34

Sheet Monthly
D2: Key Indicators | DA2: 청명절 4.5~7 | DB2: 노동절 5.1~4 | DC2: =SUM(DA11:DC11)/DC3*1000000000 -> 21251792 | DJ2: 춘절 1.24~ | DK2: 춘절 역기저 | DL2: Covid-19 | FV2: =FW2/DC2 -> 1.7196522 | FW2: =SUM(FU13:FW13)/FW3*1000000000 -> 36545691
D3: Paradise Monthly | DC3: =SUM(DA43:DC43) -> 22323 | FU3: =FU4/DA4 -> 1.3905557 | FW3: =SUM(FU43:FW43) -> 21536
D4: All Formula - No Key-in | X4: >city Grand | AJ4: >Incheon | BH4: >Busan | DA4: =SUM(CX13:DA13)*10^3/SUM(CX43:DA43) -> 26.429645 | FU4: =SUM(FR13:FU13)*10^3/SUM(FR43:FU43) -> 36.751893 | FW4: =FW3/DC3 -> 0.96474488 | GH4: ■ CHART DATA (Auto; Monthly를 Column Add 해서 밀면 저절로 밀림, 건드리지 말 것)
F5: =G5-1 -> 4 | G5: =H5-1 -> 5 | H5: =I5-1 -> 6 | I5: =J5-1 -> 7 | J5: =K5-1 -> 8 | K5: =L5-1 -> 9 | L5: =M5-1 -> 10 | M5: =N5-1 -> 11 | ... Q5: =R5-1 -> 15 | R5: 16 | S5: =R5+1 -> 17 | T5: =S5+1 -> 18 | U5: =T5+1 -> 19 | V5: =U5+1 -> 20 | W5: =V5+1 -> 21 | X5: =W5+1 -> 22 | Y5: =X5+1 -> 23 | Z5: =Y5+1 -> 24 | ... FS5: =FR5+1 -> 173 | FT5: 174 | FU5: 175 | FV5: 176 | FW5: 177 | FX5: 178 | FY5: 179 | FZ5: 180 | GA5: 181 | GB5: 182 | GC5: 183 | GD5: 184 | GE5: 185 | GS5: 17
F6: =IF(TEXT(F7,"MM")<="03","1Q"&TEXT(F7,"YY"),IF(TEXT(F7,"MM")<="06","2Q"&TEXT(F7,"YY"),IF(TEXT(F7,"MM")<="09","3Q"&TEXT(F7,"YY"),IF(TEXT(F7,"MM")<="12","4Q"&TEXT(F7,"YY"),"X")))) -> 1Q11 | G6: =IF(TEXT(G7,"MM")<="03","1Q"&TEXT(G7,"YY"),IF(TEXT(G7,"MM")<="06","2Q"&TEXT(G7,"YY"),IF(TEXT(G7,"MM")<="09","3Q"&TEXT(G7,"YY"),IF(TEXT(G7,"MM")<="12","4Q"&TEXT(G7,"YY"),"X")))) -> 1Q11 | H6: =IF(TEXT(H7,"MM")<="03","1Q"&TEXT(H7,"YY"),IF(TEXT(H7,"MM")<="06","2Q"&TEXT(H7,"YY"),IF(TEXT(H7,"MM")<="09","3Q"&TEXT(H7,"YY"),IF(TEXT(H7,"MM")<="12","4Q"&TEXT(H7,"YY"),"X")))) -> 1Q11 | I6: =IF(TEXT(I7,"MM")<="03","1Q"&TEXT(I7,"YY"),IF(TEXT(I7,"MM")<="06","2Q"&TEXT(I7,"YY"),IF(TEXT(I7,"MM")<="09","3Q"&TEXT(I7,"YY"),IF(TEXT(I7,"MM")<="12","4Q"&TEXT(I7,"YY"),"X")))) -> 2Q11 | J6: =IF(TEXT(J7,"MM")<="03","1Q"&TEXT(J7,"YY"),IF(TEXT(J7,"MM")<="06","2Q"&TEXT(J7,"YY"),IF(TEXT(J7,"MM")<="09","3Q"&TEXT(J7,"YY"),IF(TEXT(J7,"MM")<="12","4Q"&TEXT(J7,"YY"),"X")))) -> 2Q11 | K6: =IF(TEXT(K7,"MM")<="03","1Q"&TEXT(K7,"YY"),IF(TEXT(K7,"MM")<="06","2Q"&TEXT(K7,"YY"),IF(TEXT(K7,"MM")<="09","3Q"&TEXT(K7,"YY"),IF(TEXT(K7,"MM")<="12","4Q"&TEXT(K7,"YY"),"X")))) -> 2Q11 | L6: =IF(TEXT(L7,"MM")<="03","1Q"&TEXT(L7,"YY"),IF(TEXT(L7,"MM")<="06","2Q"&TEXT(L7,"YY"),IF(TEXT(L7,"MM")<="09","3Q"&TEXT(L7,"YY"),IF(TEXT(L7,"MM")<="12","4Q"&TEXT(L7,"YY"),"X")))) -> 3Q11 | M6: =IF(TEXT(M7,"MM")<="03","1Q"&TEXT(M7,"YY"),IF(TEXT(M7,"MM")<="06","2Q"&TEXT(M7,"YY"),IF(TEXT(M7,"MM")<="09","3Q"&TEXT(M7,"YY"),IF(TEXT(M7,"MM")<="12","4Q"&TEXT(M7,"YY"),"X")))) -> 3Q11 | ... GE6: =IF(TEXT(GE7,"MM")<="03","1Q"&TEXT(GE7,"YY"),IF(TEXT(GE7,"MM")<="06","2Q"&TEXT(GE7,"YY"),IF(TEXT(GE7,"MM")<="09","3Q"&TEXT(GE7,"YY"),IF(TEXT(GE7,"MM")<="12","4Q"&TEXT(GE7,"YY"),"X")))) -> 1Q26 | GI6: =GI7 -> 45659 | GJ6: =GJ7 -> 45689 | GK6: =GK7 -> 45717 | GL6: =GL7 -> 45749 | GM6: =GM7 -> 45780 | GN6: =GN7 -> 45812 | GO6: =GO7 -> 45843 | GP6: =GP7 -> 45875 | ... GV6: =GV7 -> 46054
D7: (Wbn,%, Persons) | F7: 40544 | G7: 40575 | H7: 40603 | I7: 40634 | J7: 40664 | K7: 40695 | L7: 40725 | M7: 40756 | N7: 40787 | O7: 40817 | P7: 40848 | Q7: 40878 | R7: 40909 | S7: 40940 | T7: 40969 | U7: 41000 | V7: 41030 | W7: 41061 | X7: 41091 | Y7: 41122 | Z7: 41153 | AA7: 41183 | AB7: 41214 | AC7: 41244 | AD7: 41275 | AE7: 41306 | AF7: 41334 | AG7: 41365 | AH7: 41395 | AI7: 41426 | AJ7: 41456 | AK7: 41487 | AL7: 41518 | AM7: 41548 | AN7: 41579 | AO7: 41609 | AP7: 41640 | AQ7: 41671 | AR7: 41699 | AS7: 41730 | AT7: 41760 | AU7: 41791 | AV7: 41821 | AW7: 41852 | AX7: 41883 | AY7: 41913 | AZ7: 41944 | BA7: 41974 | BB7: 42005 | BC7: 42036 | BD7: 42064 | BE7: 42095 | BF7: 42125 | BG7: 42156 | BH7: 42186 | BI7: 42217 | BJ7: 42248 | BK7: 42278 | BL7: 42309 | BM7: 42339 | BN7: 42370 | BO7: 42401 | BP7: 42430 | BQ7: 42461 | BR7: 42491 | BS7: 42522 | BT7: 42552 | BU7: 42583 | BV7: 42614 | BW7: 42644 | BX7: 42675 | BY7: 42705 | BZ7: 42736 | CA7: 42767 | CB7: 42795 | CC7: 42826 | CD7: 42856 | CE7: 42887 | CF7: 42917 | CG7: 42948 | CH7: 42979 | CI7: 43009 | CJ7: 43040 | CK7: 43070 | CL7: 43101 | CM7: 43132 | CN7: 43160 | CO7: 43191 | CP7: 43221 | CQ7: 43252 | CR7: 43282 | CS7: 43313 | CT7: 43344 | CU7: 43374 | CV7: 43405 | CW7: 43435 | CX7: 43466 | CY7: 43497 | CZ7: 43525 | DA7: 43556 | DB7: 43586 | DC7: 43617 | DD7: 43647 | DE7: 43678 | DF7: 43709 | DG7: 43739 | DH7: 43770 | DI7: 43800 | DJ7: 43831 | DK7: 43862 | DL7: 43891 | DM7: 43922 | DN7: 43952 | DO7: 43983 | DP7: 44013 | DQ7: 44044 | DR7: 44075 | DS7: 44105 | DT7: 44136 | DU7: 44166 | DV7: 44197 | DW7: 44228 | DX7: 44256 | DY7: 44287 | DZ7: 44317 | EA7: 44348 | EB7: 44378 | EC7: 44409 | ED7: 44440 | EE7: 44470 | EF7: 44501 | EG7: 44531 | EH7: 44562 | EI7: 44593 | EJ7: 44621 | EK7: 44652 | EL7: 44682 | EM7: 44713 | EN7: 44743 | EO7: 44774 | EP7: 44805 | EQ7: 44835 | ER7: 44866 | ES7: 44896 | ET7: 44927 | EU7: 44958 | EV7: 44986 | EW7: 45017 | EX7: 45047 | EY7: 45078 | EZ7: 45108 | FA7: 45139 | FB7: 45170 | FC7: 45200 | FD7: 45231 | FE7: 45261 | FF7: 45292 | FG7: 45323 | FH7: 45352 | FI7: 45383 | FJ7: 45413 | FK7: 45444 | FL7: 45474 | FM7: 45535 | FN7: 45565 | FO7: 45596 | FP7: 45597 | FQ7: 45627 | FR7: 45659 | FS7: 45689 | FT7: 45717 | FU7: 45749 | FV7: 45780 | FW7: 45812 | FX7: 45843 | FY7: 45875 | FZ7: 45907 | GA7: 45938 | GB7: 45970 | GC7: 46000 | GD7: 46031 | GE7: 46054 | GI7: =INDEX($7:$7,1,COLUMN(GI7)-$GS$5) -> 45659 | GJ7: =INDEX($7:$7,1,COLUMN(GJ7)-$GS$5) -> 45689 | GK7: =INDEX($7:$7,1,COLUMN(GK7)-$GS$5) -> 45717 | GL7: =INDEX($7:$7,1,COLUMN(GL7)-$GS$5) -> 45749 | GM7: =INDEX($7:$7,1,COLUMN(GM7)-$GS$5) -> 45780 | GN7: =INDEX($7:$7,1,COLUMN(GN7)-$GS$5) -> 45812 | GO7: =INDEX($7:$7,1,COLUMN(GO7)-$GS$5) -> 45843 | GP7: =INDEX($7:$7,1,COLUMN(GP7)-$GS$5) -> 45875 | ... GV7: =INDEX($7:$7,1,COLUMN(GV7)-$GS$5) -> 46054
D8: Consolidated | GH8: 전체 드롭액(좌) | GI8: =INDEX($9:$9,1,COLUMN(GI8)-$GS$5) -> 579.445 | GJ8: =INDEX($9:$9,1,COLUMN(GJ8)-$GS$5) -> 525.715 | GK8: =INDEX($9:$9,1,COLUMN(GK8)-$GS$5) -> 589.072 | GL8: =INDEX($9:$9,1,COLUMN(GL8)-$GS$5) -> 609.466 | GM8: =INDEX($9:$9,1,COLUMN(GM8)-$GS$5) -> 644.228 | GN8: =INDEX($9:$9,1,COLUMN(GN8)-$GS$5) -> 581.352 | GO8: =INDEX($9:$9,1,COLUMN(GO8)-$GS$5) -> 583.926 | GP8: =INDEX($9:$9,1,COLUMN(GP8)-$GS$5) -> 656.313 | ... GV8: =INDEX($9:$9,1,COLUMN(GV8)-$GS$5) -> 535.58758
D9: 드롭액 | E9: Drop | F9: =SUM(F69,F142,F92,F119) -> 317.69378 | G9: =SUM(G69,G142,G92,G119) -> 338.82352 | H9: =SUM(H69,H142,H92,H119) -> 297.04617 | I9: =SUM(I69,I142,I92,I119) -> 314.50209 | J9: =SUM(J69,J142,J92,J119) -> 353.29179 | K9: =SUM(K69,K142,K92,K119) -> 327.98878 | L9: =SUM(L69,L142,L92,L119) -> 342.24757 | M9: =SUM(M69,M142,M92,M119) -> 356.65924 | ... GE9: =SUM(GE69,GE142,GE92,GE119) -> 535.58758 | GH9: 전체%y-y(우) | GI9: =INDEX($10:$10,1,COLUMN(GI9)-$GS$5)*100 -> 1.8471413 | GJ9: =INDEX($10:$10,1,COLUMN(GJ9)-$GS$5)*100 -> -7.0240288 | GK9: =INDEX($10:$10,1,COLUMN(GK9)-$GS$5)*100 -> -1.0352271 | GL9: =INDEX($10:$10,1,COLUMN(GL9)-$GS$5)*100 -> 7.6450817 | GM9: =INDEX($10:$10,1,COLUMN(GM9)-$GS$5)*100 -> 6.3781163 | GN9: =INDEX($10:$10,1,COLUMN(GN9)-$GS$5)*100 -> 9.3099779 | GO9: =INDEX($10:$10,1,COLUMN(GO9)-$GS$5)*100 -> 7.7006502 | GP9: =INDEX($10:$10,1,COLUMN(GP9)-$GS$5)*100 -> -1.6709465 | ... GV9: =INDEX($10:$10,1,COLUMN(GV9)-$GS$5)*100 -> 1.877933
D10: y-y(%) | E10: Growth Rate(y-y) | S10: =S9/G9-1 -> 0.04962062 | T10: =T9/H9-1 -> 0.31261474 | U10: =U9/I9-1 -> 0.20706493 | V10: =V9/J9-1 -> 0.014703339 | W10: =W9/K9-1 -> 0.18811968 | X10: =X9/L9-1 -> 0.22150324 | Y10: =Y9/M9-1 -> 0.10608842 | Z10: =Z9/N9-1 -> 0.04319087 | ... GE10: =GE9/FS9-1 -> 0.01877933 | GH10: 매스 드롭액(좌) | GI10: =INDEX($17:$17,1,COLUMN(GI10)-$GS$5) -> 129.355 | GJ10: =INDEX($17:$17,1,COLUMN(GJ10)-$GS$5) -> 110.643 | GK10: =INDEX($17:$17,1,COLUMN(GK10)-$GS$5) -> 127.017 | GL10: =INDEX($17:$17,1,COLUMN(GL10)-$GS$5) -> 124.99 | GM10: =INDEX($17:$17,1,COLUMN(GM10)-$GS$5) -> 136.879 | GN10: =INDEX($17:$17,1,COLUMN(GN10)-$GS$5) -> 130.749 | GO10: =INDEX($17:$17,1,COLUMN(GO10)-$GS$5) -> 141.343 | GP10: =INDEX($17:$17,1,COLUMN(GP10)-$GS$5) -> 153.371 | ... GV10: =INDEX($17:$17,1,COLUMN(GV10)-$GS$5) -> 132.08001
D11: 중국인 VIP | E11: China VIP | F11: =SUM(F71,F144,F94,F121) -> 168.55735 | G11: =SUM(G71,G144,G94,G121) -> 187.41253 | H11: =SUM(H71,H144,H94,H121) -> 123.79515 | I11: =SUM(I71,I144,I94,I121) -> 145.48701 | J11: =SUM(J71,J144,J94,J121) -> 175.16384 | K11: =SUM(K71,K144,K94,K121) -> 180.70392 | L11: =SUM(L71,L144,L94,L121) -> 172.94715 | M11: =SUM(M71,M144,M94,M121) -> 181.33545 | ... GE11: =SUM(GE71,GE144,GE94,GE121) -> 83.853194 | GH11: 매스%y-y(우) | GI11: =INDEX($18:$18,1,COLUMN(GI11)-$GS$5)*100 -> 0.93557851 | GJ11: =INDEX($18:$18,1,COLUMN(GJ11)-$GS$5)*100 -> -1.0384244 | GK11: =INDEX($18:$18,1,COLUMN(GK11)-$GS$5)*100 -> 2.8036551 | GL11: =INDEX($18:$18,1,COLUMN(GL11)-$GS$5)*100 -> 3.4848196 | GM11: =INDEX($18:$18,1,COLUMN(GM11)-$GS$5)*100 -> 11.129243 | GN11: =INDEX($18:$18,1,COLUMN(GN11)-$GS$5)*100 -> 9.7596602 | GO11: =INDEX($18:$18,1,COLUMN(GO11)-$GS$5)*100 -> 16.471645 | GP11: =INDEX($18:$18,1,COLUMN(GP11)-$GS$5)*100 -> 21.64964 | ... GV11: =INDEX($18:$18,1,COLUMN(GV11)-$GS$5)*100 -> 19.374938
D12: y-y(%) | E12: Growth Rate(y-y) | S12: =S11/G11-1 -> 0.067441882 | T12: =T11/H11-1 -> 0.75976332 | U12: =U11/I11-1 -> 0.57483908 | V12: =V11/J11-1 -> 0.18971969 | W12: =W11/K11-1 -> 0.23601509 | X12: =X11/L11-1 -> 0.38716376 | Y12: =Y11/M11-1 -> 0.27205105 | Z12: =Z11/N11-1 -> 0.24541943 | ... GE12: =GE11/FS11-1 -> -0.22020241 | GH12: 워커힐 | GI12: =INDEX($69:$69,1,COLUMN(GI12)-$GS$5) -> 222.827 | GJ12: =INDEX($69:$69,1,COLUMN(GJ12)-$GS$5) -> 207.574 | GK12: =INDEX($69:$69,1,COLUMN(GK12)-$GS$5) -> 242.82 | GL12: =INDEX($69:$69,1,COLUMN(GL12)-$GS$5) -> 216.184 | GM12: =INDEX($69:$69,1,COLUMN(GM12)-$GS$5) -> 242.292 | GN12: =INDEX($69:$69,1,COLUMN(GN12)-$GS$5) -> 205.9 | GO12: =INDEX($69:$69,1,COLUMN(GO12)-$GS$5) -> 198.609 | GP12: =INDEX($69:$69,1,COLUMN(GP12)-$GS$5) -> 220.714 | ... GV12: =INDEX($69:$69,1,COLUMN(GV12)-$GS$5) -> 190.07046
D13: 일본인 VIP | E13: Japan VIP | F13: =SUM(F72,F145,F95,F122) -> 80.952128 | G13: =SUM(G72,G145,G95,G122) -> 95.170045 | H13: =SUM(H72,H145,H95,H122) -> 90.428219 | I13: =SUM(I72,I145,I95,I122) -> 98.587848 | J13: =SUM(J72,J145,J95,J122) -> 103.06093 | K13: =SUM(K72,K145,K95,K122) -> 77.99186 | L13: =SUM(L72,L145,L95,L122) -> 87.852964 | M13: =SUM(M72,M145,M95,M122) -> 86.426677 | ... GE13: =SUM(GE72,GE145,GE95,GE122) -> 211.97106 | GH13: 제주 | GI13: =INDEX($142:$142,1,COLUMN(GI13)-$GS$5) -> 13.372 | GJ13: =INDEX($142:$142,1,COLUMN(GJ13)-$GS$5) -> 9.923 | GK13: =INDEX($142:$142,1,COLUMN(GK13)-$GS$5) -> 16.607 | GL13: =INDEX($142:$142,1,COLUMN(GL13)-$GS$5) -> 16.302 | GM13: =INDEX($142:$142,1,COLUMN(GM13)-$GS$5) -> 13.67 | GN13: =INDEX($142:$142,1,COLUMN(GN13)-$GS$5) -> 13.724 | GO13: =INDEX($142:$142,1,COLUMN(GO13)-$GS$5) -> 13.609 | GP13: =INDEX($142:$142,1,COLUMN(GP13)-$GS$5) -> 14.57 | ... GV13: =INDEX($142:$142,1,COLUMN(GV13)-$GS$5) -> 15.06276
D14: y-y(%) | E14: Growth Rate(y-y) | S14: =S13/G13-1 -> -0.00041404835 | T14: =T13/H13-1 -> 0.04689169 | U14: =U13/I13-1 -> -0.18302579 | V14: =V13/J13-1 -> -0.14473868 | W14: =W13/K13-1 -> 0.20831628 | X14: =X13/L13-1 -> 0.17832249 | Y14: =Y13/M13-1 -> 0.030662026 | Z14: =Z13/N13-1 -> -0.19292086 | ... GE14: =GE13/FS13-1 -> -0.00315993 | GH14: P-City | GI14: =INDEX($92:$92,1,COLUMN(GI14)-$GS$5) -> 312.474 | GJ14: =INDEX($92:$92,1,COLUMN(GJ14)-$GS$5) -> 273.743 | GK14: =INDEX($92:$92,1,COLUMN(GK14)-$GS$5) -> 290.088 | GL14: =INDEX($92:$92,1,COLUMN(GL14)-$GS$5) -> 334.748 | GM14: =INDEX($92:$92,1,COLUMN(GM14)-$GS$5) -> 339.586 | GN14: =INDEX($92:$92,1,COLUMN(GN14)-$GS$5) -> 322.11 | GO14: =INDEX($92:$92,1,COLUMN(GO14)-$GS$5) -> 329.776 | GP14: =INDEX($92:$92,1,COLUMN(GP14)-$GS$5) -> 364.764 | ... GV14: =INDEX($92:$92,1,COLUMN(GV14)-$GS$5) -> 273.51478
D15: 기타 VIP | E15: Others VIP | F15: =SUM(F73,F146,F96,F123) -> 40.347536 | G15: =SUM(G73,G146,G96,G123) -> 30.738883 | H15: =SUM(H73,H146,H96,H123) -> 52.518558 | I15: =SUM(I73,I146,I96,I123) -> 41.105644 | J15: =SUM(J73,J146,J96,J123) -> 43.880898 | K15: =SUM(K73,K146,K96,K123) -> 37.876052 | L15: =SUM(L73,L146,L96,L123) -> 47.018601 | M15: =SUM(M73,M146,M96,M123) -> 45.156507 | ... BK15: =SUM(BK73,BK146,BK96,BK123) -> 46.336234 | BL15: =SUM(BL73,F130,BL96,BL123) -> 48.920467 | BM15: =SUM(BM73,BM146,BM96,BM123) -> 54.151005 | BN15: =SUM(BN73,BN146,BN96,BN123) -> 56.359603 | BO15: =SUM(BO73,BO146,BO96,BO123) -> 49.079019 | BP15: =SUM(BP73,BP146,BP96,BP123) -> 57.770647 | BQ15: =SUM(BQ73,BQ146,BQ96,BQ123) -> 56.847843 | BR15: =SUM(BR73,BR146,BR96,BR123) -> 56.644337 | BS15: =SUM(BS73,BS146,BS96,BS123) -> 48.842771 | BT15: =SUM(BT73,BT146,BT96,BT123) -> 49.985782 | ... GE15: =SUM(GE73,GE146,GE96,GE123) -> 107.68331 | GH15: 부산 | GI15: =INDEX($119:$119,1,COLUMN(GI15)-$GS$5) -> 30.772 | GJ15: =INDEX($119:$119,1,COLUMN(GJ15)-$GS$5) -> 34.475 | GK15: =INDEX($119:$119,1,COLUMN(GK15)-$GS$5) -> 39.557 | GL15: =INDEX($119:$119,1,COLUMN(GL15)-$GS$5) -> 42.232 | GM15: =INDEX($119:$119,1,COLUMN(GM15)-$GS$5) -> 48.68 | GN15: =INDEX($119:$119,1,COLUMN(GN15)-$GS$5) -> 39.618 | GO15: =INDEX($119:$119,1,COLUMN(GO15)-$GS$5) -> 41.932 | GP15: =INDEX($119:$119,1,COLUMN(GP15)-$GS$5) -> 56.265 | ... GV15: =INDEX($119:$119,1,COLUMN(GV15)-$GS$5) -> 56.939577
D16: y-y(%) | E16: Growth Rate(y-y) | S16: =S15/G15-1 -> 0.067489407 | T16: =T15/H15-1 -> -0.21086704 | U16: =U15/I15-1 -> -0.095100006 | V16: =V15/J15-1 -> -0.2957267 | W16: =W15/K15-1 -> -0.0097074795 | X16: =X15/L15-1 -> -0.11798337 | Y16: =Y15/M15-1 -> -0.065799886 | Z16: =Z15/N15-1 -> 0.0046152414 | ... GE16: =GE15/FS15-1 -> 0.13475074 | GH16: 전체VIP | GI16: =INDEX($11:$11,1,COLUMN(GI16)-$GS$5)+INDEX($13:$13,1,COLUMN(GI16)-$GS$5)+INDEX($15:$15,1,COLUMN(GI16)-$GS$5) -> 450.09 | GJ16: =INDEX($11:$11,1,COLUMN(GJ16)-$GS$5)+INDEX($13:$13,1,COLUMN(GJ16)-$GS$5)+INDEX($15:$15,1,COLUMN(GJ16)-$GS$5) -> 415.071 | GK16: =INDEX($11:$11,1,COLUMN(GK16)-$GS$5)+INDEX($13:$13,1,COLUMN(GK16)-$GS$5)+INDEX($15:$15,1,COLUMN(GK16)-$GS$5) -> 462.05496 | GL16: =INDEX($11:$11,1,COLUMN(GL16)-$GS$5)+INDEX($13:$13,1,COLUMN(GL16)-$GS$5)+INDEX($15:$15,1,COLUMN(GL16)-$GS$5) -> 484.477 | GM16: =INDEX($11:$11,1,COLUMN(GM16)-$GS$5)+INDEX($13:$13,1,COLUMN(GM16)-$GS$5)+INDEX($15:$15,1,COLUMN(GM16)-$GS$5) -> 507.35 | GN16: =INDEX($11:$11,1,COLUMN(GN16)-$GS$5)+INDEX($13:$13,1,COLUMN(GN16)-$GS$5)+INDEX($15:$15,1,COLUMN(GN16)-$GS$5) -> 450.603 | GO16: =INDEX($11:$11,1,COLUMN(GO16)-$GS$5)+INDEX($13:$13,1,COLUMN(GO16)-$GS$5)+INDEX($15:$15,1,COLUMN(GO16)-$GS$5) -> 442.582 | GP16: =INDEX($11:$11,1,COLUMN(GP16)-$GS$5)+INDEX($13:$13,1,COLUMN(GP16)-$GS$5)+INDEX($15:$15,1,COLUMN(GP16)-$GS$5) -> 502.942 | ... GV16: =INDEX($11:$11,1,COLUMN(GV16)-$GS$5)+INDEX($13:$13,1,COLUMN(GV16)-$GS$5)+INDEX($15:$15,1,COLUMN(GV16)-$GS$5) -> 403.50756
D17: 매스 | E17: Mass | F17: =SUM(F74,F147,F97,F124) -> 27.836763 | G17: =SUM(G74,G147,G97,G124) -> 25.502057 | H17: =SUM(H74,H147,H97,H124) -> 30.304238 | I17: =SUM(I74,I147,I97,I124) -> 29.321592 | J17: =SUM(J74,J147,J97,J124) -> 31.186132 | K17: =SUM(K74,K147,K97,K124) -> 31.416951 | L17: =SUM(L74,L147,L97,L124) -> 34.428856 | M17: =SUM(M74,M147,M97,M124) -> 43.740602 | ... BK17: =SUM(BK74,BK147,BK97,BK124) -> 45.75965 | BL17: =SUM(BL74,F131,BL97,BL124) -> 36.010456 | BM17: =SUM(BM74,BM147,BM97,BM124) -> 43.769561 | BN17: =SUM(BN74,BN147,BN97,BN124) -> 40.662433 | BO17: =SUM(BO74,BO147,BO97,BO124) -> 40.487021 | BP17: =SUM(BP74,BP147,BP97,BP124) -> 39.478178 | BQ17: =SUM(BQ74,BQ147,BQ97,BQ124) -> 44.4981 | BR17: =SUM(BR74,BR147,BR97,BR124) -> 48.919375 | BS17: =SUM(BS74,BS147,BS97,BS124) -> 49.030206 | BT17: =SUM(BT74,BT147,BT97,BT124) -> 53.905196 | ... GE17: =SUM(GE74,GE147,GE97,GE124) -> 132.08001 | GH17: 중국VIP | GI17: =INDEX($11:$11,1,COLUMN(GI17)-$GS$5) -> 98.808 | GJ17: =INDEX($11:$11,1,COLUMN(GJ17)-$GS$5) -> 107.532 | GK17: =INDEX($11:$11,1,COLUMN(GK17)-$GS$5) -> 96.622155 | GL17: =INDEX($11:$11,1,COLUMN(GL17)-$GS$5) -> 95.553 | GM17: =INDEX($11:$11,1,COLUMN(GM17)-$GS$5) -> 91.327 | GN17: =INDEX($11:$11,1,COLUMN(GN17)-$GS$5) -> 106.089 | GO17: =INDEX($11:$11,1,COLUMN(GO17)-$GS$5) -> 104.942 | GP17: =INDEX($11:$11,1,COLUMN(GP17)-$GS$5) -> 113.886 | ... GV17: =INDEX($11:$11,1,COLUMN(GV17)-$GS$5) -> 83.853194
D18: y-y(%) | E18: Growth Rate(y-y) | S18: =S17/G17-1 -> 0.083837747 | T18: =T17/H17-1 -> 0.18611572 | U18: =U17/I17-1 -> 0.11745621 | V18: =V17/J17-1 -> -0.0046111522 | W18: =W17/K17-1 -> 0.1009964 | X18: =X17/L17-1 -> -0.036849032 | Y18: =Y17/M17-1 -> -0.25545625 | Z18: =Z17/N17-1 -> 0.019273853 | ... GE18: =GE17/FS17-1 -> 0.19374938 | GH18: 일본VIP | GI18: =INDEX($13:$13,1,COLUMN(GI18)-$GS$5) -> 259.406 | GJ18: =INDEX($13:$13,1,COLUMN(GJ18)-$GS$5) -> 212.643 | GK18: =INDEX($13:$13,1,COLUMN(GK18)-$GS$5) -> 248.42702 | GL18: =INDEX($13:$13,1,COLUMN(GL18)-$GS$5) -> 260.432 | GM18: =INDEX($13:$13,1,COLUMN(GM18)-$GS$5) -> 286.386 | GN18: =INDEX($13:$13,1,COLUMN(GN18)-$GS$5) -> 240.23 | GO18: =INDEX($13:$13,1,COLUMN(GO18)-$GS$5) -> 237.036 | GP18: =INDEX($13:$13,1,COLUMN(GP18)-$GS$5) -> 289.936 | ... GV18: =INDEX($13:$13,1,COLUMN(GV18)-$GS$5) -> 211.97106
D19: 정킷(롤링칩) | E19: Rolling Chip Rate | F19: =SUM(F75,F148,F98,F125) -> 0 | G19: =SUM(G75,G148,G98,G125) -> 0 | H19: =SUM(H75,H148,H98,H125) -> 0 | I19: =SUM(I75,I148,I98,I125) -> 0 | J19: =SUM(J75,J148,J98,J125) -> 0 | K19: =SUM(K75,K148,K98,K125) -> 0 | L19: =SUM(L75,L148,L98,L125) -> 0 | M19: =SUM(M75,M148,M98,M125) -> 0 | ... GE19: =SUM(GE75,GE148,GE98,GE125) -> 0 | GH19: 매출액(좌) | GI19: =INDEX($22:$22,1,COLUMN(GI19)-$GS$5) -> 71.749 | GJ19: =INDEX($22:$22,1,COLUMN(GJ19)-$GS$5) -> 70.217 | GK19: =INDEX($22:$22,1,COLUMN(GK19)-$GS$5) -> 81.921 | GL19: =INDEX($22:$22,1,COLUMN(GL19)-$GS$5) -> 67.234 | GM19: =INDEX($22:$22,1,COLUMN(GM19)-$GS$5) -> 81.749 | GN19: =INDEX($22:$22,1,COLUMN(GN19)-$GS$5) -> 80.802 | GO19: =INDEX($22:$22,1,COLUMN(GO19)-$GS$5) -> 75.201 | GP19: =INDEX($22:$22,1,COLUMN(GP19)-$GS$5) -> 79.391 | ... GV19: =INDEX($22:$22,1,COLUMN(GV19)-$GS$5) -> 89.509075
D20: W/L | E20: Win/Loss | F20: =SUM(F76,F149,F99,F126) -> 0 | G20: =SUM(G76,G149,G99,G126) -> 0 | H20: =SUM(H76,H149,H99,H126) -> 0 | I20: =SUM(I76,I149,I99,I126) -> 0 | J20: =SUM(J76,J149,J99,J126) -> 0 | K20: =SUM(K76,K149,K99,K126) -> 0 | L20: =SUM(L76,L149,L99,L126) -> 0 | M20: =SUM(M76,M149,M99,M126) -> 0 | ... GE20: =SUM(GE76,GE149,GE99,GE126) -> 0 | GH20: %y-y(우) | GI20: =INDEX($23:$23,1,COLUMN(GI20)-$GS$5)*100 -> -0.50752271 | GJ20: =INDEX($23:$23,1,COLUMN(GJ20)-$GS$5)*100 -> -11.510882 | GK20: =INDEX($23:$23,1,COLUMN(GK20)-$GS$5)*100 -> 53.464716 | GL20: =INDEX($23:$23,1,COLUMN(GL20)-$GS$5)*100 -> -17.521499 | GM20: =INDEX($23:$23,1,COLUMN(GM20)-$GS$5)*100 -> 8.8288936 | GN20: =INDEX($23:$23,1,COLUMN(GN20)-$GS$5)*100 -> 39.687095 | GO20: =INDEX($23:$23,1,COLUMN(GO20)-$GS$5)*100 -> 22.131094 | GP20: =INDEX($23:$23,1,COLUMN(GP20)-$GS$5)*100 -> 10.236188 | ... GV20: =INDEX($23:$23,1,COLUMN(GV20)-$GS$5)*100 -> 27.474935
D21: 승률 | E21: Win Rate | F21: =F20/F19 -> #DIV/0! | G21: =G20/G19 -> #DIV/0! | H21: =H20/H19 -> #DIV/0! | I21: =I20/I19 -> #DIV/0! | J21: =J20/J19 -> #DIV/0! | K21: =K20/K19 -> #DIV/0! | L21: =L20/L19 -> #DIV/0! | M21: =M20/M19 -> #DIV/0! | ... GE21: =GE20/GE19 -> #DIV/0! | GH21: P-City 매출액 | GI21: =INDEX($101:$101,1,COLUMN(GI21)-$GS$5) -> 35.256 | GJ21: =INDEX($101:$101,1,COLUMN(GJ21)-$GS$5) -> 36.066 | GK21: =INDEX($101:$101,1,COLUMN(GK21)-$GS$5) -> 36.708 | GL21: =INDEX($101:$101,1,COLUMN(GL21)-$GS$5) -> 39.094 | GM21: =INDEX($101:$101,1,COLUMN(GM21)-$GS$5) -> 46.668 | GN21: =INDEX($101:$101,1,COLUMN(GN21)-$GS$5) -> 42.434 | GO21: =INDEX($101:$101,1,COLUMN(GO21)-$GS$5) -> 40.321 | GP21: =INDEX($101:$101,1,COLUMN(GP21)-$GS$5) -> 45.291 | ... GV21: =INDEX($101:$101,1,COLUMN(GV21)-$GS$5) -> 40.029664
D22: 매출액 | E22: Sales | F22: =SUM(F78,F151,F101,F128) -> 49.739 | G22: =SUM(G78,G151,G101,G128) -> 39.243 | H22: =SUM(H78,H151,H101,H128) -> 36.705 | I22: =SUM(I78,I151,I101,I128) -> 36.708 | J22: =SUM(J78,J151,J101,J128) -> 37.924 | K22: =SUM(K78,K151,K101,K128) -> 36.535 | L22: =SUM(L78,L151,L101,L128) -> 45.402 | M22: =SUM(M78,M151,M101,M128) -> 45.108 | ... BK22: =SUM(BK78,BK151,BK101,BK128) -> 67.126 | BL22: =SUM(BL78,F133,BL101,BL128) -> 49.207793 | BM22: =SUM(BM78,BM151,BM101,BM128) -> 39.66 | BN22: =SUM(BN78,BN151,BN101,BN128) -> 56.399 | BO22: =SUM(BO78,BO151,BO101,BO128) -> 37.54 | BP22: =SUM(BP78,BP151,BP101,BP128) -> 44.029 | BQ22: =SUM(BQ78,BQ151,BQ101,BQ128) -> 56.081 | BR22: =SUM(BR78,BR151,BR101,BR128) -> 59.719 | BS22: =SUM(BS78,BS151,BS101,BS128) -> 50.943 | BT22: =SUM(BT78,BT151,BT101,BT128) -> 49.127 | ... GE22: =SUM(GE78,GE151,GE101,GE128) -> 89.509075 | GH22: %y-y(우) | GI22: =INDEX($102:$102,1,COLUMN(GI22)-$GS$5)*100 -> -9.6115883 | GJ22: =INDEX($102:$102,1,COLUMN(GJ22)-$GS$5)*100 -> 12.509359 | GK22: =INDEX($102:$102,1,COLUMN(GK22)-$GS$5)*100 -> 16.459391 | GL22: =INDEX($102:$102,1,COLUMN(GL22)-$GS$5)*100 -> 6.5376754 | GM22: =INDEX($102:$102,1,COLUMN(GM22)-$GS$5)*100 -> 30.510655 | GN22: =INDEX($102:$102,1,COLUMN(GN22)-$GS$5)*100 -> 41.136167 | GO22: =INDEX($102:$102,1,COLUMN(GO22)-$GS$5)*100 -> 35.038012 | GP22: =INDEX($102:$102,1,COLUMN(GP22)-$GS$5)*100 -> 6.112647 | ... GV22: =INDEX($102:$102,1,COLUMN(GV22)-$GS$5)*100 -> 10.990029
D23: y-y(%) | E23: Growth Rate(y-y) | S23: =S22/G22-1 -> 0.032056673 | T23: =T22/H22-1 -> 0.31491622 | U23: =U22/I22-1 -> 0.4587011 | V23: =V22/J22-1 -> 0.45786309 | W23: =W22/K22-1 -> 0.038647872 | X23: =X22/L22-1 -> 0.017157834 | Y23: =Y22/M22-1 -> 0.011173184 | Z23: =Z22/N22-1 -> 0.48764388 | ... GE23: =GE22/FS22-1 -> 0.27474935 | GH23: 홀드율 | GI23: =INDEX($30:$30,1,COLUMN(GI23)-$GS$5)*100 -> 11.6 | GJ23: =INDEX($30:$30,1,COLUMN(GJ23)-$GS$5)*100 -> 12.5 | GK23: =INDEX($30:$30,1,COLUMN(GK23)-$GS$5)*100 -> 13.2 | GL23: =INDEX($30:$30,1,COLUMN(GL23)-$GS$5)*100 -> 10.4 | GM23: =INDEX($30:$30,1,COLUMN(GM23)-$GS$5)*100 -> 12 | GN23: =INDEX($30:$30,1,COLUMN(GN23)-$GS$5)*100 -> 13.1 | GO23: =INDEX($30:$30,1,COLUMN(GO23)-$GS$5)*100 -> 12.1 | GP23: =INDEX($30:$30,1,COLUMN(GP23)-$GS$5)*100 -> 11.4 | ... GV23: =INDEX($30:$30,1,COLUMN(GV23)-$GS$5)*100 -> 15.866758
B24: Dart | C24: 3 | D24: 테이블 | E24: Table Sales | F24: =SUM(F80,F153,F103,F130) -> 48.064 | G24: =SUM(G80,G153,G103,G130) -> 37.257 | H24: =SUM(H80,H153,H103,H130) -> 34.534 | I24: =SUM(I80,I153,I103,I130) -> 34.904 | J24: =SUM(J80,J153,J103,J130) -> 35.771 | K24: =SUM(K80,K153,K103,K130) -> 34.815 | L24: =SUM(L80,L153,L103,L130) -> 43.634 | M24: =SUM(M80,M153,M103,M130) -> 43.267 | ... BK24: =SUM(BK80,BK153,BK103,BK130) -> 64.011 | BL24: =SUM(BL80,F136,BL103,BL130) -> 2389.715 | BM24: =SUM(BM80,BM153,BM103,BM130) -> 36.405 | BN24: =SUM(BN80,BN153,BN103,BN130) -> 53.498 | BO24: =SUM(BO80,BO153,BO103,BO130) -> 34.885 | BP24: =SUM(BP80,BP153,BP103,BP130) -> 41.28 | BQ24: =SUM(BQ80,BQ153,BQ103,BQ130) -> 52.762 | BR24: =SUM(BR80,BR153,BR103,BR130) -> 56.539 | BS24: =SUM(BS80,BS153,BS103,BS130) -> 47.872 | BT24: =SUM(BT80,BT153,BT103,BT130) -> 45.67 | ... GE24: =SUM(GE80,GE153,GE103,GE130) -> 84.980387 | GH24: 워커힐 | GI24: =INDEX($83:$83,1,COLUMN(GI24)-$GS$5)*100 -> 12.5 | GJ24: =INDEX($83:$83,1,COLUMN(GJ24)-$GS$5)*100 -> 12.9 | GK24: =INDEX($83:$83,1,COLUMN(GK24)-$GS$5)*100 -> 14.6 | GL24: =INDEX($83:$83,1,COLUMN(GL24)-$GS$5)*100 -> 10.6 | GM24: =INDEX($83:$83,1,COLUMN(GM24)-$GS$5)*100 -> 11.5 | GN24: =INDEX($83:$83,1,COLUMN(GN24)-$GS$5)*100 -> 14.6 | GO24: =INDEX($83:$83,1,COLUMN(GO24)-$GS$5)*100 -> 14.1 | GP24: =INDEX($83:$83,1,COLUMN(GP24)-$GS$5)*100 -> 12.6 | ... GV24: =INDEX($83:$83,1,COLUMN(GV24)-$GS$5)*100 -> 14.740011
D25: y-y(%) | E25: Growth Rate(y-y) | S25: =S24/G24-1 -> 0.027028478 | T25: =T24/H24-1 -> 0.32924075 | U25: =U24/I24-1 -> 0.45172473 | V25: =V24/J24-1 -> 0.45738168 | W25: =W24/K24-1 -> 0.016199914 | X25: =X24/L24-1 -> -0.0064628501 | Y25: =Y24/M24-1 -> -0.0094298195 | Z25: =Z24/N24-1 -> 0.50641323 | ... GE25: =GE24/FS24-1 -> 0.28849919 | GH25: 제주 | GI25: =INDEX($156:$156,1,COLUMN(GI25)-$GS$5)*100 -> 18.1 | GJ25: =INDEX($156:$156,1,COLUMN(GJ25)-$GS$5)*100 -> 12 | GK25: =INDEX($156:$156,1,COLUMN(GK25)-$GS$5)*100 -> 20 | GL25: =INDEX($156:$156,1,COLUMN(GL25)-$GS$5)*100 -> 12.6 | GM25: =INDEX($156:$156,1,COLUMN(GM25)-$GS$5)*100 -> 4.1 | GN25: =INDEX($156:$156,1,COLUMN(GN25)-$GS$5)*100 -> 15.6 | GO25: =INDEX($156:$156,1,COLUMN(GO25)-$GS$5)*100 -> 13 | GP25: =INDEX($156:$156,1,COLUMN(GP25)-$GS$5)*100 -> 1.2 | ... GV25: =INDEX($156:$156,1,COLUMN(GV25)-$GS$5)*100 -> 19.531613
B26: Dart | C26: 4 | D26: 머신 | E26: Machine Sales | F26: =SUM(F81,F154,F104,F131) -> 1.675 | G26: =SUM(G81,G154,G104,G131) -> 1.986 | H26: =SUM(H81,H154,H104,H131) -> 2.171 | I26: =SUM(I81,I154,I104,I131) -> 1.804 | J26: =SUM(J81,J154,J104,J131) -> 2.153 | K26: =SUM(K81,K154,K104,K131) -> 1.72 | L26: =SUM(L81,L154,L104,L131) -> 1.768 | M26: =SUM(M81,M154,M104,M131) -> 1.841 | ... BK26: =SUM(BK81,BK154,BK104,BK131) -> 3.115 | BL26: =SUM(BL81,F137,BL104,BL131) -> #REF! | BM26: =SUM(BM81,BM154,BM104,BM131) -> 3.255 | BN26: =SUM(BN81,BN154,BN104,BN131) -> 2.901 | BO26: =SUM(BO81,BO154,BO104,BO131) -> 2.655 | BP26: =SUM(BP81,BP154,BP104,BP131) -> 2.749 | BQ26: =SUM(BQ81,BQ154,BQ104,BQ131) -> 3.319 | BR26: =SUM(BR81,BR154,BR104,BR131) -> 3.18 | BS26: =SUM(BS81,BS154,BS104,BS131) -> 3.071 | BT26: =SUM(BT81,BT154,BT104,BT131) -> 3.457 | ... GE26: =SUM(GE81,GE154,GE104,GE131) -> 4.5286883 | GH26: P-City | GI26: =INDEX($106:$106,1,COLUMN(GI26)-$GS$5)*100 -> 10.4 | GJ26: =INDEX($106:$106,1,COLUMN(GJ26)-$GS$5)*100 -> 12.4 | GK26: =INDEX($106:$106,1,COLUMN(GK26)-$GS$5)*100 -> 12 | GL26: =INDEX($106:$106,1,COLUMN(GL26)-$GS$5)*100 -> 11 | GM26: =INDEX($106:$106,1,COLUMN(GM26)-$GS$5)*100 -> 13 | GN26: =INDEX($106:$106,1,COLUMN(GN26)-$GS$5)*100 -> 12.4 | GO26: =INDEX($106:$106,1,COLUMN(GO26)-$GS$5)*100 -> 11.5 | GP26: =INDEX($106:$106,1,COLUMN(GP26)-$GS$5)*100 -> 11.8 | ... GV26: =INDEX($106:$106,1,COLUMN(GV26)-$GS$5)*100 -> 13.750918
D27: y-y(%) | E27: Growth Rate(y-y) | S27: =S26/G26-1 -> 0.12638469 | T27: =T26/H26-1 -> 0.087056656 | U27: =U26/I26-1 -> 0.59368071 | V27: =V26/J26-1 -> 0.46586159 | W27: =W26/K26-1 -> 0.49302326 | X27: =X26/L26-1 -> 0.60011312 | Y27: =Y26/M26-1 -> 0.49538294 | Z27: =Z26/N26-1 -> 0.19391462 | ... GE27: =GE26/FS26-1 -> 0.06207511 | GH27: 부산 | GI27: =INDEX($133:$133,1,COLUMN(GI27)-$GS$5)*100 -> 13.7 | GJ27: =INDEX($133:$133,1,COLUMN(GJ27)-$GS$5)*100 -> 11.9 | GK27: =INDEX($133:$133,1,COLUMN(GK27)-$GS$5)*100 -> 10.5 | GL27: =INDEX($133:$133,1,COLUMN(GL27)-$GS$5)*100 -> 4.2 | GM27: =INDEX($133:$133,1,COLUMN(GM27)-$GS$5)*100 -> 9 | GN27: =INDEX($133:$133,1,COLUMN(GN27)-$GS$5)*100 -> 10.1 | GO27: =INDEX($133:$133,1,COLUMN(GO27)-$GS$5)*100 -> 7.9 | GP27: =INDEX($133:$133,1,COLUMN(GP27)-$GS$5)*100 -> 7.2 | ... GV27: =INDEX($133:$133,1,COLUMN(GV27)-$GS$5)*100 -> 28.822111
B28: Dart | C28: 5 | D28: 정킷 | E28: Junket Sales | CL28: =CL22-CL24-CL26 -> -0.738 | CM28: =CM22-CM24-CM26 -> 0.626 | CN28: =CN22-CN24-CN26 -> 0.772 | CO28: =CO22-CO24-CO26 -> 2.913 | CP28: =CP22-CP24-CP26 -> -2.69 | CQ28: =CQ22-CQ24-CQ26 -> 1.887 | CR28: =CR22-CR24-CR26 -> 2.305 | CS28: =CS22-CS24-CS26 -> 0.529 | ... GE28: =GE22-GE24-GE26 -> 1.0658141e-14 | GH28: 매스 드롭액 비중 | GI28: =INDEX($177:$177,1,COLUMN(GI28)-$GS$5)*100 -> 22.323948 | GJ28: =INDEX($177:$177,1,COLUMN(GJ28)-$GS$5)*100 -> 21.046194 | GK28: =INDEX($177:$177,1,COLUMN(GK28)-$GS$5)*100 -> 21.56222 | GL28: =INDEX($177:$177,1,COLUMN(GL28)-$GS$5)*100 -> 20.508117 | GM28: =INDEX($177:$177,1,COLUMN(GM28)-$GS$5)*100 -> 21.246981 | GN28: =INDEX($177:$177,1,COLUMN(GN28)-$GS$5)*100 -> 22.490505 | GO28: =INDEX($177:$177,1,COLUMN(GO28)-$GS$5)*100 -> 24.205636 | GP28: =INDEX($177:$177,1,COLUMN(GP28)-$GS$5)*100 -> 23.368576 | ... GV28: =INDEX($177:$177,1,COLUMN(GV28)-$GS$5)*100 -> 24.660769
D29: %W/L | E29: %W/L | S29: =S28/G28-1 -> #DIV/0! | T29: =T28/H28-1 -> #DIV/0! | U29: =U28/I28-1 -> #DIV/0! | V29: =V28/J28-1 -> #DIV/0! | W29: =W28/K28-1 -> #DIV/0! | X29: =X28/L28-1 -> #DIV/0! | Y29: =Y28/M28-1 -> #DIV/0! | Z29: =Z28/N28-1 -> #DIV/0! | ... BN29: =BN28/BB28-1 -> #DIV/0! | BP29: =BP28/BD28-1 -> #DIV/0! | BQ29: =BQ28/BE28-1 -> #DIV/0! | BR29: =BR28/BF28-1 -> #DIV/0! | BS29: =BS28/BG28-1 -> #DIV/0! | BT29: =BT28/BH28-1 -> #DIV/0! | BU29: =BU28/BI28-1 -> #DIV/0! | BV29: =BV28/BJ28-1 -> #DIV/0! | BW29: =BW28/BK28-1 -> #DIV/0! | ... BZ29: =BZ28/BN28-1 -> #DIV/0! | CA29: =CA28/CA20 -> #DIV/0! | CB29: =CB28/CB20 -> #DIV/0! | CC29: =CC28/CC20 -> #DIV/0! | CD29: =CD28/CD20 -> #DIV/0! | CE29: =CE28/CE20 -> #DIV/0! | CF29: =CF28/CF20 -> #DIV/0! | CG29: =CG28/CG20 -> #DIV/0! | CH29: =CH28/CH20 -> #DIV/0! | ... GE29: =GE28/GE20 -> #DIV/0!
B30: Property | C30: =Property!P1 -> 16 | D30: 홀드율 | E30: Hold Rate | F30: =INDEX(Property!$A$1:$W$95,F$5,$C30) -> 0.15129034 | G30: =INDEX(Property!$A$1:$W$95,G$5,$C30) -> 0.1099599 | H30: =INDEX(Property!$A$1:$W$95,H$5,$C30) -> 0.11625802 | I30: =INDEX(Property!$A$1:$W$95,I$5,$C30) -> 0.11098177 | J30: =INDEX(Property!$A$1:$W$95,J$5,$C30) -> 0.10125058 | K30: =INDEX(Property!$A$1:$W$95,K$5,$C30) -> 0.10614692 | L30: =INDEX(Property!$A$1:$W$95,L$5,$C30) -> 0.1274925 | M30: =INDEX(Property!$A$1:$W$95,M$5,$C30) -> 0.12131187 | ... CS30: =INDEX(Property!$A$1:$W$95,CS$5,$C30) -> 0.096790018 | CT30: =INDEX(Property!$A$1:$W$259,CT$5,$C30) -> 0.10251402 | CU30: =INDEX(Property!$A$1:$W$259,CU$5,$C30) -> 0.12726044 | CV30: =INDEX(Property!$A$1:$W$259,CV$5,$C30) -> 0.097277352 | CW30: =INDEX(Property!$A$1:$W$259,CW$5,$C30) -> 0.10282646 | CX30: =INDEX(Property!$A$1:$W$259,CX$5,$C30) -> 0.097791806 | CY30: =INDEX(Property!$A$1:$W$259,CY$5,$C30) -> 0.10497297 | CZ30: =INDEX(Property!$A$1:$W$259,CZ$5,$C30) -> 0.095496626 | DA30: =INDEX(Property!$A$1:$W$259,DA$5,$C30) -> 0.088208583 | ... GE30: =INDEX(Property!$A$1:$W$259,GE$5,$C30) -> 0.15866758 | GH30: 홀드율 | GI30: =GI23 -> 11.6 | GJ30: =GJ23 -> 12.5 | GK30: =GK23 -> 13.2 | GL30: =GL23 -> 10.4 | GM30: =GM23 -> 12 | GN30: =GN23 -> 13.1 | GO30: =GO23 -> 12.1 | GP30: =GP23 -> 11.4 | ... GV30: =GV23 -> 15.866758
D31: 테이블 | E31: Hold Rate(Table) | F31: =F24/F9 -> 0.15129034 | G31: =G24/G9 -> 0.1099599 | H31: =H24/H9 -> 0.11625802 | I31: =I24/I9 -> 0.11098177 | J31: =J24/J9 -> 0.10125058 | K31: =K24/K9 -> 0.10614692 | L31: =L24/L9 -> 0.1274925 | M31: =M24/M9 -> 0.12131187 | ... GE31: =GE24/GE9 -> 0.15866758
D32: 매스 고객수 | E32: No. of MASS | F32: =#REF!-F33 -> #REF! | G32: =#REF!-G33 -> #REF! | H32: =#REF!-H33 -> #REF! | I32: =#REF!-I33 -> #REF! | J32: =#REF!-J33 -> #REF! | K32: =#REF!-K33 -> #REF! | L32: =#REF!-L33 -> #REF! | M32: =#REF!-M33 -> #REF! | ... CO32: =#REF!-CO33 -> #REF!
D33: VIP고객수 | E33: No. of VIPs | F33: =SUM(F86,F159,F109,F136) -> 13597 | G33: =SUM(G86,G159,G109,G136) -> 13681 | H33: =SUM(H86,H159,H109,H136) -> 11851 | I33: =SUM(I86,I159,I109,I136) -> 13269 | J33: =SUM(J86,J159,J109,J136) -> 14846 | K33: =SUM(K86,K159,K109,K136) -> 12464 | L33: =SUM(L86,L159,L109,L136) -> 13959 | M33: =SUM(M86,M159,M109,M136) -> 13567 | ... BK33: =SUM(BK86,BK159,BK109,BK136) -> 14484 | BL33: =SUM(BL86,F140,BL109,BL136) -> 12005 | BM33: =SUM(BM86,BM159,BM109,BM136) -> 13262 | BN33: =SUM(BN86,BN159,BN109,BN136) -> 14005 | BO33: =SUM(BO86,BO159,BO109,BO136) -> 12544 | BP33: =SUM(BP86,BP159,BP109,BP136) -> 13350 | BQ33: =SUM(BQ86,BQ159,BQ109,BQ136) -> 13193 | BR33: =SUM(BR86,BR159,BR109,BR136) -> 15301 | BS33: =SUM(BS86,BS159,BS109,BS136) -> 12929 | BT33: =SUM(BT86,BT159,BT109,BT136) -> 14002 | ... GE33: =SUM(GE86,GE159,GE109,GE136) -> 12665 | GH33: [Paradise City]
D34: y-y(%) | E34: Growth Rate(y-y) | S34: =S33/G33-1 -> -0.072143849 | T34: =T33/H33-1 -> 0.21609991 | U34: =U33/I33-1 -> 0.16022308 | V34: =V33/J33-1 -> 0.035160986 | W34: =W33/K33-1 -> 0.18485237 | X34: =X33/L33-1 -> 0.091124006 | Y34: =Y33/M33-1 -> 0.16599101 | Z34: =Z33/N33-1 -> 0.067980368 | ... GE34: =GE33/FS33-1 -> 0.021206257 | GH34: 매스 드롭액 비중 | GI34: =INDEX($183:$183,1,COLUMN(GI34)-$GS$5)*100 -> 21.341616 | GJ34: =INDEX($183:$183,1,COLUMN(GJ34)-$GS$5)*100 -> 20.38043 | GK34: =INDEX($183:$183,1,COLUMN(GK34)-$GS$5)*100 -> 21.473139 | GL34: =INDEX($183:$183,1,COLUMN(GL34)-$GS$5)*100 -> 19.878834 | GM34: =INDEX($183:$183,1,COLUMN(GM34)-$GS$5)*100 -> 21.216128 | GN34: =INDEX($183:$183,1,COLUMN(GN34)-$GS$5)*100 -> 21.666201 | GO34: =INDEX($183:$183,1,COLUMN(GO34)-$GS$5)*100 -> 23.499891 | GP34: =INDEX($183:$183,1,COLUMN(GP34)-$GS$5)*100 -> 24.294338 | ... GV34: =INDEX($183:$183,1,COLUMN(GV34)-$GS$5)*100 -> 26.049213
D35: 인당 지출액 | E35: Spending per VIP | CA35: =CA9*10^3/CA33 -> 33.21602 | CB35: =CB9*10^3/CB33 -> 33.236166 | CC35: =CC9*10^3/CC33 -> 30.882954 | CD35: =CD9*10^3/CD33 -> 32.119952 | CE35: =CE9*10^3/CE33 -> 31.380231 | CF35: =CF9*10^3/CF33 -> 32.320634 | CG35: =CG9*10^3/CG33 -> 32.560065 | CH35: =CH9*10^3/CH33 -> 34.094896 | ... GE35: =GE9*10^3/GE33 -> 42.288794 | GH35: 홀드율 | GI35: =GI26 -> 10.4 | GJ35: =GJ26 -> 12.4 | GK35: =GK26 -> 12 | GL35: =GL26 -> 11 | GM35: =GM26 -> 13 | GN35: =GN26 -> 12.4 | GO35: =GO26 -> 11.5 | GP35: =GP26 -> 11.8 | ... GV35: =GV26 -> 13.750918
D36: y-y(%) | E36: Growth Rate(y-y) | CA36: =CA35/BO35-1 -> #DIV/0! | CB36: =CB35/BP35-1 -> #DIV/0! | CC36: =CC35/BQ35-1 -> #DIV/0! | CD36: =CD35/BR35-1 -> #DIV/0! | CE36: =CE35/BS35-1 -> #DIV/0! | CF36: =CF35/BT35-1 -> #DIV/0! | CG36: =CG35/BU35-1 -> #DIV/0! | CH36: =CH35/BV35-1 -> #DIV/0! | ... GE36: =GE35/FS35-1 -> -0.0023765296
D37: 중국인 VIP | E37: China VIP | F37: =SUM(F88,F161,F111,F138) -> 4644 | G37: =SUM(G88,G161,G111,G138) -> 5344 | H37: =SUM(H88,H161,H111,H138) -> 3918 | I37: =SUM(I88,I161,I111,I138) -> 4785 | J37: =SUM(J88,J161,J111,J138) -> 5290 | K37: =SUM(K88,K161,K111,K138) -> 4786 | L37: =SUM(L88,L161,L111,L138) -> 5019 | M37: =SUM(M88,M161,M111,M138) -> 5264 | ... GE37: =SUM(GE88,GE161,GE111,GE138) -> 2741
D38: y-y(%) | E38: Growth Rate(y-y) | S38: =S37/G37-1 -> 0.012537425 | T38: =T37/H37-1 -> 0.47269015 | U38: =U37/I37-1 -> 0.33396029 | V38: =V37/J37-1 -> 0.1 | W38: =W37/K37-1 -> 0.26138738 | X38: =X37/L37-1 -> 0.20263001 | Y38: =Y37/M37-1 -> 0.19243921 | Z38: =Z37/N37-1 -> 0.21593431 | ... GE38: =GE37/FS37-1 -> -0.027669386
D39: 시티제외 | E39: Excl. P-City | BQ39: =BQ37-BQ111 -> 3972 | BR39: =BR37-BR111 -> 4513 | BS39: =BS37-BS111 -> 4278 | BT39: =BT37-BT111 -> 4019 | BU39: =BU37-BU111 -> 3360 | BV39: =BV37-BV111 -> 3078 | BW39: =BW37-BW111 -> 4557 | BX39: =BX37-BX111 -> 2967 | ... GE39: =GE37-GE111 -> 1653
D40: y-y(%) | E40: Growth Rate(y-y) | CA40: =CA39/BO39-1 -> #DIV/0! | CB40: =CB39/BP39-1 -> #DIV/0! | CC40: =CC39/BQ39-1 -> -0.50981873 | CD40: =CD39/BR39-1 -> -0.43208509 | CE40: =CE39/BS39-1 -> -0.51238897 | CF40: =CF39/BT39-1 -> -0.25578502 | CG40: =CG39/BU39-1 -> -0.20386905 | CH40: =CH39/BV39-1 -> -0.24041585 | ... GE40: =GE39/FS39-1 -> -0.0012084592
D41: 인당 지출액 | E41: Spending per VIP | BR41: =BR11*10^3/BR37 -> 37.145908 | BS41: =BS11*10^3/BS37 -> 39.600737 | BT41: =BT11*10^3/BT37 -> 39.031458 | BU41: =BU11*10^3/BU37 -> 41.376944 | BV41: =BV11*10^3/BV37 -> 43.575266 | BW41: =BW11*10^3/BW37 -> 38.888477 | BX41: =BX11*10^3/BX37 -> 46.103134 | BY41: =BY11*10^3/BY37 -> 43.671157 | ... GE41: =GE11*10^3/GE37 -> 30.59219
...

Sheet Quarterly
D2: Key Indicators
D3: Paradise Quarterly | X3: 중국 공안의 불법 마케팅 관련 체포 | AE3: 2017년 4월 1차개장
F4: Walkerhill Only | L4: >Jeju Grand | P4: >Incheon | X4: >Busan | AE4: >P-City | AJ4: >P-City 2nd
F5: =G5-1 -> 182 | G5: =H5-1 -> 183 | H5: =I5-1 -> 184 | I5: =J5-1 -> 185 | J5: =K5-1 -> 186 | K5: =L5-1 -> 187 | L5: =M5-1 -> 188 | M5: =N5-1 -> 189 | ... BF5: =BG5-1 -> 234 | BG5: 235 | BH5: =BG5+1 -> 236 | BI5: =BH5+1 -> 237 | BJ5: =BI5+1 -> 238 | BK5: =BJ5+1 -> 239 | BL5: =BK5+1 -> 240 | BM5: =BL5+1 -> 241
D7: (Wbn,%, Persons) | F7: 1Q11 | G7: 2Q11 | H7: 3Q11 | I7: 4Q11 | J7: 1Q12 | K7: 2Q12 | L7: 3Q12 | M7: 4Q12 | N7: 1Q13 | O7: 2Q13 | P7: 3Q13 | Q7: 4Q13 | R7: 1Q14 | S7: 2Q14 | T7: 3Q14 | U7: 4Q14 | V7: 1Q15 | W7: 2Q15 | X7: 3Q15 | Y7: 4Q15 | Z7: 1Q16 | AA7: 2Q16 | AB7: 3Q16 | AC7: 4Q16 | AD7: 1Q17 | AE7: 2Q17 | AF7: 3Q17 | AG7: 4Q17 | AH7: 1Q18 | AI7: 2Q18 | AJ7: 3Q18 | AK7: 4Q18 | AL7: 1Q19 | AM7: 2Q19 | AN7: 3Q19 | AO7: 4Q19 | AP7: 1Q20 | AQ7: 2Q20 | AR7: 3Q20 | AS7: 4Q20 | AT7: 1Q21 | AU7: 2Q21 | AV7: 3Q21 | AW7: 4Q21 | AX7: 1Q22 | AY7: 2Q22 | AZ7: 3Q22 | BA7: 4Q22 | BB7: 1Q23 | BC7: 2Q23 | BD7: 3Q23 | BE7: 4Q23 | BF7: 1Q24 | BG7: 2Q24 | BH7: 3Q24 | BI7: 4Q24 | BJ7: 1Q25 | BK7: 2Q25 | BL7: 3Q25 | BM7: 4Q25
D8: Consolidated
D9: 드롭액 | E9: Drop | F9: =SUMIF(Monthly!$6:$6,Quarterly!F$7,Monthly!9:9) -> 953.56347 | G9: =SUMIF(Monthly!$6:$6,Quarterly!G$7,Monthly!9:9) -> 995.78266 | H9: =SUMIF(Monthly!$6:$6,Quarterly!H$7,Monthly!9:9) -> 1060.9248 | I9: =SUMIF(Monthly!$6:$6,Quarterly!I$7,Monthly!9:9) -> 1163.7018 | J9: =SUMIF(Monthly!$6:$6,Quarterly!J$7,Monthly!9:9) -> 1099.9075 | K9: =SUMIF(Monthly!$6:$6,Quarterly!K$7,Monthly!9:9) -> 1127.8007 | L9: =SUMIF(Monthly!$6:$6,Quarterly!L$7,Monthly!9:9) -> 1190.207 | M9: =SUMIF(Monthly!$6:$6,Quarterly!M$7,Monthly!9:9) -> 1250.1375 | ... BM9: =SUMIF(Monthly!$6:$6,Quarterly!BM$7,Monthly!9:9) -> 1812.542
D10: y-y(%) | E10: Growth Rate(y-y) | J10: =J9/F9-1 -> 0.15347073 | K10: =K9/G9-1 -> 0.13257719 | L10: =L9/H9-1 -> 0.12185805 | M10: =M9/I9-1 -> 0.07427646 | N10: =N9/J9-1 -> 0.17307554 | O10: =O9/K9-1 -> 0.15670393 | P10: =P9/L9-1 -> 0.14115111 | Q10: =Q9/M9-1 -> 0.23461181 | ... BM10: =BM9/BI9-1 -> 0.090609006
D11: 중국인 VIP | E11: China VIP | F11: =SUMIF(Monthly!$6:$6,Quarterly!F$7,Monthly!11:11) -> 479.76504 | G11: =SUMIF(Monthly!$6:$6,Quarterly!G$7,Monthly!11:11) -> 501.35476 | H11: =SUMIF(Monthly!$6:$6,Quarterly!H$7,Monthly!11:11) -> 508.27859 | I11: =SUMIF(Monthly!$6:$6,Quarterly!I$7,Monthly!11:11) -> 600.60338 | J11: =SUMIF(Monthly!$6:$6,Quarterly!J$7,Monthly!11:11) -> 618.86179 | K11: =SUMIF(Monthly!$6:$6,Quarterly!K$7,Monthly!11:11) -> 660.86725 | L11: =SUMIF(Monthly!$6:$6,Quarterly!L$7,Monthly!11:11) -> 662.36357 | M11: =SUMIF(Monthly!$6:$6,Quarterly!M$7,Monthly!11:11) -> 708.76325 | ... BM11: =SUMIF(Monthly!$6:$6,Quarterly!BM$7,Monthly!11:11) -> 301.82626
D12: 일본인 VIP | E12: Japan VIP | F12: =SUMIF(Monthly!$6:$6,Quarterly!F$7,Monthly!13:13) -> 266.55039 | G12: =SUMIF(Monthly!$6:$6,Quarterly!G$7,Monthly!13:13) -> 279.64064 | H12: =SUMIF(Monthly!$6:$6,Quarterly!H$7,Monthly!13:13) -> 293.78394 | I12: =SUMIF(Monthly!$6:$6,Quarterly!I$7,Monthly!13:13) -> 284.68791 | J12: =SUMIF(Monthly!$6:$6,Quarterly!J$7,Monthly!13:13) -> 277.44034 | K12: =SUMIF(Monthly!$6:$6,Quarterly!K$7,Monthly!13:13) -> 262.92659 | L12: =SUMIF(Monthly!$6:$6,Quarterly!L$7,Monthly!13:13) -> 289.04524 | M12: =SUMIF(Monthly!$6:$6,Quarterly!M$7,Monthly!13:13) -> 310.24645 | ... BM12: =SUMIF(Monthly!$6:$6,Quarterly!BM$7,Monthly!13:13) -> 723.23978
D13: 기타 VIP | E13: Others VIP | F13: =SUMIF(Monthly!$6:$6,Quarterly!F$7,Monthly!15:15) -> 123.60498 | G13: =SUMIF(Monthly!$6:$6,Quarterly!G$7,Monthly!15:15) -> 122.86259 | H13: =SUMIF(Monthly!$6:$6,Quarterly!H$7,Monthly!15:15) -> 147.36052 | I13: =SUMIF(Monthly!$6:$6,Quarterly!I$7,Monthly!15:15) -> 154.9576 | J13: =SUMIF(Monthly!$6:$6,Quarterly!J$7,Monthly!15:15) -> 108.42705 | K13: =SUMIF(Monthly!$6:$6,Quarterly!K$7,Monthly!15:15) -> 105.60901 | L13: =SUMIF(Monthly!$6:$6,Quarterly!L$7,Monthly!15:15) -> 139.09651 | M13: =SUMIF(Monthly!$6:$6,Quarterly!M$7,Monthly!15:15) -> 125.15281 | ... BM13: =SUMIF(Monthly!$6:$6,Quarterly!BM$7,Monthly!15:15) -> 345.10917
D14: 매스 | E14: Mass | F14: =SUMIF(Monthly!$6:$6,Quarterly!F$7,Monthly!17:17) -> 83.643058 | G14: =SUMIF(Monthly!$6:$6,Quarterly!G$7,Monthly!17:17) -> 91.924675 | H14: =SUMIF(Monthly!$6:$6,Quarterly!H$7,Monthly!17:17) -> 111.50177 | I14: =SUMIF(Monthly!$6:$6,Quarterly!I$7,Monthly!17:17) -> 123.45293 | J14: =SUMIF(Monthly!$6:$6,Quarterly!J$7,Monthly!17:17) -> 95.178368 | K14: =SUMIF(Monthly!$6:$6,Quarterly!K$7,Monthly!17:17) -> 98.397873 | L14: =SUMIF(Monthly!$6:$6,Quarterly!L$7,Monthly!17:17) -> 99.701727 | M14: =SUMIF(Monthly!$6:$6,Quarterly!M$7,Monthly!17:17) -> 105.97497 | ... BM14: =SUMIF(Monthly!$6:$6,Quarterly!BM$7,Monthly!17:17) -> 442.36503
D15: 정킷 | E15: Rolling Chip Rate | F15: =SUMIF(Monthly!$6:$6,Quarterly!F$7,Monthly!19:19) -> 0 | G15: =SUMIF(Monthly!$6:$6,Quarterly!G$7,Monthly!19:19) -> 0 | H15: =SUMIF(Monthly!$6:$6,Quarterly!H$7,Monthly!19:19) -> 0 | I15: =SUMIF(Monthly!$6:$6,Quarterly!I$7,Monthly!19:19) -> 0 | J15: =SUMIF(Monthly!$6:$6,Quarterly!J$7,Monthly!19:19) -> 0 | K15: =SUMIF(Monthly!$6:$6,Quarterly!K$7,Monthly!19:19) -> 0 | L15: =SUMIF(Monthly!$6:$6,Quarterly!L$7,Monthly!19:19) -> 0 | M15: =SUMIF(Monthly!$6:$6,Quarterly!M$7,Monthly!19:19) -> 0 | ... BM15: =SUMIF(Monthly!$6:$6,Quarterly!BM$7,Monthly!19:19) -> 0
D16: W/L | E16: Win/Loss | F16: =SUMIF(Monthly!$6:$6,Quarterly!F$7,Monthly!20:20) -> 0 | G16: =SUMIF(Monthly!$6:$6,Quarterly!G$7,Monthly!20:20) -> 0 | H16: =SUMIF(Monthly!$6:$6,Quarterly!H$7,Monthly!20:20) -> 0 | I16: =SUMIF(Monthly!$6:$6,Quarterly!I$7,Monthly!20:20) -> 0 | J16: =SUMIF(Monthly!$6:$6,Quarterly!J$7,Monthly!20:20) -> 0 | K16: =SUMIF(Monthly!$6:$6,Quarterly!K$7,Monthly!20:20) -> 0 | L16: =SUMIF(Monthly!$6:$6,Quarterly!L$7,Monthly!20:20) -> 0 | M16: =SUMIF(Monthly!$6:$6,Quarterly!M$7,Monthly!20:20) -> 0 | ... BM16: =SUMIF(Monthly!$6:$6,Quarterly!BM$7,Monthly!20:20) -> 0
B17: Property | C17: =Property!I$1 -> 9 | D17: 홀드율 | E17: Hold Rate | F17: =INDEX(Property!$A$1:$W$259,F$5,$C17) -> 0 | G17: =INDEX(Property!$A$1:$W$259,G$5,$C17) -> 0 | H17: =INDEX(Property!$A$1:$W$259,H$5,$C17) -> 0 | I17: =INDEX(Property!$A$1:$W$259,I$5,$C17) -> 0 | J17: =INDEX(Property!$A$1:$W$259,J$5,$C17) -> 0 | K17: =INDEX(Property!$A$1:$W$259,K$5,$C17) -> 0 | L17: =INDEX(Property!$A$1:$W$259,L$5,$C17) -> 0 | M17: =INDEX(Property!$A$1:$W$259,M$5,$C17) -> 0 | ... BM17: =INDEX(Property!$A$1:$W$259,BM$5,$C17) -> 0
D18: 인당 드롭액 | E18: Drop per Visitor | F18: =F9*10^9/SUM(F30,F31) -> 10399183 | G18: =G9*10^9/SUM(G30,G31) -> 8466099.8 | H18: =H9*10^9/SUM(H30,H31) -> 6415189.6 | I18: =I9*10^9/SUM(I30,I31) -> 7138968.4 | J18: =J9*10^9/SUM(J30,J31) -> 8020384.8 | K18: =K9*10^9/SUM(K30,K31) -> 6349335.6 | L18: =L9*10^9/SUM(L30,L31) -> 6537300.3 | M18: =M9*10^9/SUM(M30,M31) -> 7602300.4 | ... BM18: =BM9*10^9/SUM(BM30,BM31) -> 9581958
D19: y-y(%) | E19: Growth Rate(y-y) | J19: =J18/F18-1 -> -0.22874856 | K19: =K18/G18-1 -> -0.25002827 | L19: =L18/H18-1 -> 0.01903462 | M19: =M18/I18-1 -> 0.064901807 | N19: =N18/J18-1 -> 0.12174045 | O19: =O18/K18-1 -> 0.099519621 | P19: =P18/L18-1 -> -0.044550309 | Q19: =Q18/M18-1 -> 0.094092731 | ... BM19: =BM18/BI18-1 -> -0.47405044
D20: 중국인 VIP | E20: China VIP | F20: =F11*10^9/F33 -> 34500578 | G20: =G11*10^9/G33 -> 33736273 | H20: =H11*10^9/H33 -> 34368693 | I20: =I11*10^9/I33 -> 34849912 | J20: =J11*10^9/J33 -> 35679550 | K20: =K11*10^9/K33 -> 36233744 | L20: =L11*10^9/L33 -> 37228168 | M20: =M11*10^9/M33 -> 34673609 | ... BM20: =BM11*10^9/BM33 -> 30595667
D21: 일본인 VIP | E21: Japan VIP | F21: =F12*10^9/F34 -> 14814116 | G21: =G12*10^9/G34 -> 14764553 | H21: =H12*10^9/H34 -> 14857082 | I21: =I12*10^9/I34 -> 15926596 | J21: =J12*10^9/J34 -> 15440802 | K21: =K12*10^9/K34 -> 13640809 | L21: =L12*10^9/L34 -> 14256942 | M21: =M12*10^9/M34 -> 16258592 | ... BM21: =BM12*10^9/BM34 -> 35796861
D22: 기타 VIP | E22: Others VIP | F22: =F13*10^9/F35 -> 17096124 | G22: =G13*10^9/G35 -> 18126674 | H22: =H13*10^9/H35 -> 22280091 | I22: =I13*10^9/I35 -> 22493482 | J22: =J13*10^9/J35 -> 16917936 | K22: =K13*10^9/K35 -> 13173134 | L22: =L13*10^9/L35 -> 18391711 | M22: =M13*10^9/M35 -> 17271986 | ... BM22: =BM13*10^9/BM35 -> 27357049
D23: 매스 | E23: Mass | F23: =F14*10^9/F30 -> 1591170.5 | G23: =G14*10^9/G30 -> 1193191.6 | H23: =H14*10^9/H30 -> 897759.78 | I23: =I14*10^9/I30 -> 1020196.3 | J23: =J14*10^9/J30 -> 997499.06 | K23: =K14*10^9/K30 -> 744907.97 | L23: =L14*10^9/L30 -> 730763.57 | M23: =M14*10^9/M30 -> 900588.67 | ... BM23: =BM14*10^9/BM30 -> 3020010.8
D24: 매출액 | E24: Sales | F24: =SUMIF(Monthly!$6:$6,Quarterly!F$7,Monthly!22:22) -> 125.687 | G24: =SUMIF(Monthly!$6:$6,Quarterly!G$7,Monthly!22:22) -> 111.167 | H24: =SUMIF(Monthly!$6:$6,Quarterly!H$7,Monthly!22:22) -> 127.172 | I24: =SUMIF(Monthly!$6:$6,Quarterly!I$7,Monthly!22:22) -> 158.078 | J24: =SUMIF(Monthly!$6:$6,Quarterly!J$7,Monthly!22:22) -> 149.124 | K24: =SUMIF(Monthly!$6:$6,Quarterly!K$7,Monthly!22:22) -> 146.781 | L24: =SUMIF(Monthly!$6:$6,Quarterly!L$7,Monthly!22:22) -> 146.333 | M24: =SUMIF(Monthly!$6:$6,Quarterly!M$7,Monthly!22:22) -> 127.301 | ... BM24: =SUMIF(Monthly!$6:$6,Quarterly!BM$7,Monthly!22:22) -> 227.08584
D25: y-y(%) | E25: Growth Rate(y-y) | J25: =J24/F24-1 -> 0.18647115 | K25: =K24/G24-1 -> 0.32036486 | L25: =L24/H24-1 -> 0.15066996 | M25: =M24/I24-1 -> -0.19469502 | N25: =N24/J24-1 -> 0.101625 | O25: =O24/K24-1 -> 0.12323802 | P25: =P24/L24-1 -> 0.035227871 | Q25: =Q24/M24-1 -> 0.29303776 | ... BM25: =BM24/BI24-1 -> 0.11429111
D26: 테이블 | E26: Table Sales | F26: =SUMIF(Monthly!$6:$6,Quarterly!F$7,Monthly!24:24) -> 119.855 | G26: =SUMIF(Monthly!$6:$6,Quarterly!G$7,Monthly!24:24) -> 105.49 | H26: =SUMIF(Monthly!$6:$6,Quarterly!H$7,Monthly!24:24) -> 121.361 | I26: =SUMIF(Monthly!$6:$6,Quarterly!I$7,Monthly!24:24) -> 150.806 | J26: =SUMIF(Monthly!$6:$6,Quarterly!J$7,Monthly!24:24) -> 142.135 | K26: =SUMIF(Monthly!$6:$6,Quarterly!K$7,Monthly!24:24) -> 138.182 | L26: =SUMIF(Monthly!$6:$6,Quarterly!L$7,Monthly!24:24) -> 138.122 | M26: =SUMIF(Monthly!$6:$6,Quarterly!M$7,Monthly!24:24) -> 119.639 | ... BM26: =SUMIF(Monthly!$6:$6,Quarterly!BM$7,Monthly!24:24) -> 212.65501
D27: 머신 | E27: Machine Sales | F27: =SUMIF(Monthly!$6:$6,Quarterly!F$7,Monthly!26:26) -> 5.832 | G27: =SUMIF(Monthly!$6:$6,Quarterly!G$7,Monthly!26:26) -> 5.677 | H27: =SUMIF(Monthly!$6:$6,Quarterly!H$7,Monthly!26:26) -> 5.811 | I27: =SUMIF(Monthly!$6:$6,Quarterly!I$7,Monthly!26:26) -> 7.272 | J27: =SUMIF(Monthly!$6:$6,Quarterly!J$7,Monthly!26:26) -> 6.989 | K27: =SUMIF(Monthly!$6:$6,Quarterly!K$7,Monthly!26:26) -> 8.599 | L27: =SUMIF(Monthly!$6:$6,Quarterly!L$7,Monthly!26:26) -> 8.211 | M27: =SUMIF(Monthly!$6:$6,Quarterly!M$7,Monthly!26:26) -> 7.662 | ... BM27: =SUMIF(Monthly!$6:$6,Quarterly!BM$7,Monthly!26:26) -> 14.430827
B28: Property | C28: =Property!P$1 -> 16 | D28: 홀드율 | E28: Hold Rate | F28: =INDEX(Property!$A$1:$W$259,F$5,$C28) -> 0.12669561 | G28: =INDEX(Property!$A$1:$W$259,G$5,$C28) -> 0.11423988 | H28: =INDEX(Property!$A$1:$W$259,H$5,$C28) -> 0.13708311 | I28: =INDEX(Property!$A$1:$W$259,I$5,$C28) -> 0.15866758 | J28: =INDEX(Property!$A$1:$W$259,J$5,$C28) -> 0 | K28: =INDEX(Property!$A$1:$W$259,K$5,$C28) -> 0.12959162 | L28: =INDEX(Property!$A$1:$W$259,L$5,$C28) -> 0.1292245 | M28: =INDEX(Property!$A$1:$W$259,M$5,$C28) -> 0.12252342 | ... BM28: =INDEX(Property!$A$1:$W$259,BM$5,$C28) -> 0.10217588
D29: 테이블 | E29: Hold Rate(Table) | F29: =F26/F9 -> 0.12569169 | G29: =G26/G9 -> 0.10593677 | H29: =H26/H9 -> 0.11439171 | I29: =I26/I9 -> 0.12959162 | J29: =J26/J9 -> 0.1292245 | K29: =K26/K9 -> 0.12252342 | L29: =L26/L9 -> 0.11604872 | M29: =M26/M9 -> 0.095700675 | ... BM29: =BM26/BM9 -> 0.11732419
D30: 매스 고객수 | E30: No. of MASS | F30: =F175-F31 -> 52567 | G30: =G175-G31 -> 77041 | H30: =H175-H31 -> 124200 | I30: =I175-I31 -> 121009 | J30: =J175-J31 -> 95417 | K30: =K175-K31 -> 132094 | L30: =L175-L31 -> 136435 | M30: =M175-M31 -> 117673 | ... BM30: =BM175-BM31 -> 146477.96
D31: VIP고객수 | E31: No. of VIPs | F31: =SUMIF(Monthly!$6:$6,Quarterly!F$7,Monthly!33:33) -> 39129 | G31: =SUMIF(Monthly!$6:$6,Quarterly!G$7,Monthly!33:33) -> 40579 | H31: =SUMIF(Monthly!$6:$6,Quarterly!H$7,Monthly!33:33) -> 41177 | I31: =SUMIF(Monthly!$6:$6,Quarterly!I$7,Monthly!33:33) -> 41998 | J31: =SUMIF(Monthly!$6:$6,Quarterly!J$7,Monthly!33:33) -> 41722 | K31: =SUMIF(Monthly!$6:$6,Quarterly!K$7,Monthly!33:33) -> 45531 | L31: =SUMIF(Monthly!$6:$6,Quarterly!L$7,Monthly!33:33) -> 45629 | M31: =SUMIF(Monthly!$6:$6,Quarterly!M$7,Monthly!33:33) -> 46769 | ... BM31: =SUMIF(Monthly!$6:$6,Quarterly!BM$7,Monthly!33:33) -> 42684
D32: y-y(%) | E32: Growth Rate(y-y)
D33: 중국인 VIP | E33: China VIP | F33: =SUMIF(Monthly!$6:$6,Quarterly!F$7,Monthly!37:37) -> 13906 | G33: =SUMIF(Monthly!$6:$6,Quarterly!G$7,Monthly!37:37) -> 14861 | H33: =SUMIF(Monthly!$6:$6,Quarterly!H$7,Monthly!37:37) -> 14789 | I33: =SUMIF(Monthly!$6:$6,Quarterly!I$7,Monthly!37:37) -> 17234 | J33: =SUMIF(Monthly!$6:$6,Quarterly!J$7,Monthly!37:37) -> 17345 | K33: =SUMIF(Monthly!$6:$6,Quarterly!K$7,Monthly!37:37) -> 18239 | L33: =SUMIF(Monthly!$6:$6,Quarterly!L$7,Monthly!37:37) -> 17792 | M33: =SUMIF(Monthly!$6:$6,Quarterly!M$7,Monthly!37:37) -> 20441 | ... BM33: =SUMIF(Monthly!$6:$6,Quarterly!BM$7,Monthly!37:37) -> 9865
D34: 일본인 VIP | E34: Japan VIP | F34: =SUMIF(Monthly!$6:$6,Quarterly!F$7,Monthly!43:43) -> 17993 | G34: =SUMIF(Monthly!$6:$6,Quarterly!G$7,Monthly!43:43) -> 18940 | H34: =SUMIF(Monthly!$6:$6,Quarterly!H$7,Monthly!43:43) -> 19774 | I34: =SUMIF(Monthly!$6:$6,Quarterly!I$7,Monthly!43:43) -> 17875 | J34: =SUMIF(Monthly!$6:$6,Quarterly!J$7,Monthly!43:43) -> 17968 | K34: =SUMIF(Monthly!$6:$6,Quarterly!K$7,Monthly!43:43) -> 19275 | L34: =SUMIF(Monthly!$6:$6,Quarterly!L$7,Monthly!43:43) -> 20274 | M34: =SUMIF(Monthly!$6:$6,Quarterly!M$7,Monthly!43:43) -> 19082 | ... BM34: =SUMIF(Monthly!$6:$6,Quarterly!BM$7,Monthly!43:43) -> 20204
D35: 기타 VIP | E35: Others VIP | F35: =SUMIF(Monthly!$6:$6,Quarterly!F$7,Monthly!47:47) -> 7230 | G35: =SUMIF(Monthly!$6:$6,Quarterly!G$7,Monthly!47:47) -> 6778 | H35: =SUMIF(Monthly!$6:$6,Quarterly!H$7,Monthly!47:47) -> 6614 | I35: =SUMIF(Monthly!$6:$6,Quarterly!I$7,Monthly!47:47) -> 6889 | J35: =SUMIF(Monthly!$6:$6,Quarterly!J$7,Monthly!47:47) -> 6409 | K35: =SUMIF(Monthly!$6:$6,Quarterly!K$7,Monthly!47:47) -> 8017 | L35: =SUMIF(Monthly!$6:$6,Quarterly!L$7,Monthly!47:47) -> 7563 | M35: =SUMIF(Monthly!$6:$6,Quarterly!M$7,Monthly!47:47) -> 7246 | ... BM35: =SUMIF(Monthly!$6:$6,Quarterly!BM$7,Monthly!47:47) -> 12615
D36: Actual Cons.
D37: 드롭액 | E37: Drop | F37: =F62 -> 580.678 | G37: =G62 -> 560.07 | H37: =H62 -> 605.297 | I37: =I62 -> 679.967 | J37: =J62 -> 641.007 | K37: =K62 -> 671.564 | L37: =L62+L146 -> 788.6088 | M37: =M62+M146 -> 819.781 | N37: =N62+N146 -> 854.784 | O37: =O62+O146 -> 853.0438 | P37: =P62+P146+P90 -> 1147.959 | Q37: =Q62+Q146+Q90 -> 1334.377 | R37: =R62+R146+R90 -> 1431.258 | S37: =S62+S146+S90 -> 1314.8076 | T37: =T62+T146+T90 -> 1248.7565 | U37: =U62+U146+U90 -> 1299.287 | V37: =V62+V146+V90 -> 1107.3826 | W37: =W62+W146+W90 -> 1036.4659 | X37: =X62+X146+X90+X118 -> 1040.4344 | Y37: =Y62+Y146+Y90+Y118 -> 1158.3598 | Z37: =Z62+Z146+Z90+Z118 -> 1232.5406 | AA37: =AA62+AA146+AA90+AA118 -> 1199.1128 | AB37: =AB62+AB146+AB90+AB118 -> 1171.5756 | AC37: =AC62+AC146+AC90+AC118 -> 1228.8496 | AD37: =AD62+AD146+AD90+AD118 -> 1198.9705 | AE37: =AE62+AE146+AE90+AE118 -> 1123.2204 | ... BM37: =BM62+BM146+BM90+BM118 -> 1812.542
D38: y-y(%) | E38: Growth Rate(y-y) | J38: =J37/F37-1 -> 0.10389407 | K38: =K37/G37-1 -> 0.19907154 | L38: =L37/H37-1 -> 0.30284604 | M38: =M37/I37-1 -> 0.2056188 | N38: =N37/J37-1 -> 0.33350182 | O38: =O37/K37-1 -> 0.27023456 | P38: =P37/L37-1 -> 0.45567612 | Q38: =Q37/M37-1 -> 0.62772375 | ... BM38: =BM37/BI37-1 -> 0.090609006
D39: 중국인 VIP | E39: China VIP | F39: =F64 -> 260.756 | G39: =G64 -> 239.449 | H39: =H64 -> 214.619 | I39: =I64 -> 267.497 | J39: =J64 -> 309.974 | K39: =K64 -> 372.789 | L39: =L64+L148 -> 415.0054 | M39: =M64+M148 -> 428.638 | N39: =N64+N148 -> 477.35 | O39: =O64+O148 -> 457.4511 | P39: =P64+P148+P92 -> 677.975 | Q39: =Q64+Q148+Q92 -> 774.573 | R39: =R64+R148+R92 -> 911.227 | S39: =S64+S148+S92 -> 836.77126 | T39: =T64+T148+T92 -> 784.04184 | U39: =U64+U148+U92 -> 846.04574 | V39: =V64+V148+V92 -> 666.31002 | W39: =W64+W148+W92 -> 593.2975 | X39: =X64+X148+X92+X120 -> 502.31937 | Y39: =Y64+Y148+Y92+Y120 -> 612.96093 | Z39: =Z64+Z148+Z92+Z120 -> 652.34167 | AA39: =AA64+AA148+AA92+AA120 -> 606.92243 | AB39: =AB64+AB148+AB92+AB120 -> 517.85769 | AC39: =AC64+AC148+AC92+AC120 -> 563.63101 | AD39: =AD64+AD148+AD92+AD120 -> 535.1297 | AE39: =AE64+AE148+AE92+AE120 -> 390.9753 | ... BM39: =BM64+BM148+BM92+BM120 -> 301.82626
D40: 일본인 VIP | E40: Japan VIP | F40: =F65 -> 169.612 | G40: =G65 -> 164.047 | H40: =H65 -> 195.212 | I40: =I65 -> 199.46 | J40: =J65 -> 182.864 | K40: =K65 -> 152.962 | L40: =L65+L149 -> 194.3542 | M40: =M65+M149 -> 215.4 | N40: =N65+N149 -> 190.032 | O40: =O65+O149 -> 167.4488 | P40: =P65+P149+P93 -> 233.057 | Q40: =Q65+Q149+Q93 -> 252.808 | R40: =R65+R149+R93 -> 263.451 | S40: =S65+S149+S93 -> 200.3046 | T40: =T65+T149+T93 -> 226.8575 | U40: =U65+U149+U93 -> 213.81483 | V40: =V65+V149+V93 -> 200.55222 | W40: =W65+W149+W93 -> 175.90297 | X40: =X65+X149+X93+X121 -> 263.31484 | Y40: =Y65+Y149+Y93+Y121 -> 271.27046 | Z40: =Z65+Z149+Z93+Z121 -> 296.36207 | AA40: =AA65+AA149+AA93+AA121 -> 287.40771 | AB40: =AB65+AB149+AB93+AB121 -> 331.76315 | AC40: =AC65+AC149+AC93+AC121 -> 307.33733 | AD40: =AD65+AD149+AD93+AD121 -> 320.47641 | AE40: =AE65+AE149+AE93+AE121 -> 362.13609 | ... BM40: =BM65+BM149+BM93+BM121 -> 723.23978
D41: 기타 VIP | E41: Others VIP | F41: =F66 -> 86.541 | G41: =G66 -> 87.384 | H41: =H66 -> 109.114 | I41: =I66 -> 117.17 | J41: =J66 -> 76.311 | K41: =K66 -> 75.136 | L41: =L66+L150 -> 101.6148 | M41: =M66+M150 -> 89.95 | N41: =N66+N150 -> 106.06 | O41: =O66+O150 -> 142.1272 | P41: =P66+P150+P94 -> 132.27 | Q41: =Q66+Q150+Q94 -> 193.182 | R41: =R66+R150+R94 -> 139.451 | S41: =S66+S150+S94 -> 134.6197 | T41: =T66+T150+T94 -> 103.50702 | U41: =U66+U150+U94 -> 102.26837 | V41: =V66+V150+V94 -> 112.46058 | W41: =W66+W150+W94 -> 139.39568 | X41: =X66+X150+X94+X122 -> 148.47886 | Y41: =Y66+Y150+Y94+Y122 -> 144.56671 | Z41: =Z66+Z150+Z94+Z122 -> 163.20927 | AA41: =AA66+AA150+AA94+AA122 -> 162.33495 | AB41: =AB66+AB150+AB94+AB122 -> 163.52016 | AC41: =AC66+AC150+AC94+AC122 -> 182.13847 | AD41: =AD66+AD150+AD94+AD122 -> 163.20993 | AE41: =AE66+AE150+AE94+AE122 -> 190.43926 | ... BM41: =BM66+BM150+BM94+BM122 -> 345.10917
D42: 매스 | E42: Mass | F42: =F67 -> 63.769 | G42: =G67 -> 69.19 | H42: =H67 -> 86.352 | I42: =I67 -> 95.84 | J42: =J67 -> 71.858 | K42: =K67 -> 70.677 | L42: =L67+L151 -> 77.6344 | M42: =M67+M151 -> 85.793 | N42: =N67+N151 -> 81.342 | O42: =O67+O151 -> 86.0167 | P42: =P67+P151+P95 -> 104.657 | Q42: =Q67+Q151+Q95 -> 113.814 | R42: =R67+R151+R95 -> 117.129 | S42: =S67+S151+S95 -> 143.112 | T42: =T67+T151+T95 -> 134.3501 | U42: =U67+U151+U95 -> 137.15809 | V42: =V67+V151+V95 -> 128.0598 | W42: =W67+W151+W95 -> 127.8698 | X42: =X67+X151+X95+X123 -> 126.32134 | Y42: =Y67+Y151+Y95+Y123 -> 129.56167 | Z42: =Z67+Z151+Z95+Z123 -> 120.62763 | AA42: =AA67+AA151+AA95+AA123 -> 142.44768 | AB42: =AB67+AB151+AB95+AB123 -> 158.4346 | AC42: =AC67+AC151+AC95+AC123 -> 175.74278 | AD42: =AD67+AD151+AD95+AD123 -> 180.15442 | AE42: =AE67+AE151+AE95+AE123 -> 179.66972 | ... BM42: =BM67+BM151+BM95+BM123 -> 442.36503
...

Sheet Property
B1: Paradise: Operating metrics | C1: 3 | D1: =C1+1 -> 4 | E1: =D1+1 -> 5 | F1: =E1+1 -> 6 | G1: =F1+1 -> 7 | H1: =G1+1 -> 8 | I1: =H1+1 -> 9 | J1: =I1+1 -> 10 | K1: =J1+1 -> 11 | ... W1: =V1+1 -> 23
C2: Rolling Chip Turnover | I2: Win rate % | J2: Drop | P2: Hold % | R2: Sales
B3: (KRW mn) | C3: Walkerhill | D3: P-City | E3: Busan | F3: Jeju Grand | G3: Total | H3: Y/Y% | J3: Walkerhill | K3: P-City | L3: Busan | M3: Jeju Grand | N3: Total | O3: Y/Y% | R3: =J3 -> Walkerhill | S3: =K3 -> P-City | T3: =L3 -> Busan | U3: =M3 -> Jeju Grand | V3: =N3 -> Total | W3: Y/Y%
B4: 40574 | J4: =Walkerhill!K4 -> 195632 | K4: =City!K4 -> 68535 | L4: =Busan!K4 -> 44284.781 | M4: =Jeju!K4 -> 9242 | N4: =SUM(J4:M4) -> 317693.78 | P4: =Segment!K4 -> 0.15129034 | R4: =Walkerhill!P4 -> 32279 | S4: =City!P4 -> 9765 | T4: =Busan!P4 -> 6341 | U4: =Jeju!P4 -> 1354 | V4: =SUM(R4:U4) -> 49739
B5: 40602 | J5: =Walkerhill!K5 -> 212399 | K5: =City!K5 -> 60372 | L5: =Busan!K5 -> 50124.518 | M5: =Jeju!K5 -> 15928 | N5: =SUM(J5:M5) -> 338823.52 | P5: =Segment!K5 -> 0.1099599 | R5: =Walkerhill!P5 -> 29538 | S5: =City!P5 -> 3576 | T5: =Busan!P5 -> 5157 | U5: =Jeju!P5 -> 972 | V5: =SUM(R5:U5) -> 39243
B6: 40633 | J6: =Walkerhill!K6 -> 172647 | K6: =City!K6 -> 59855 | L6: =Busan!K6 -> 52672.168 | M6: =Jeju!K6 -> 11872 | N6: =SUM(J6:M6) -> 297046.17 | P6: =Segment!K6 -> 0.11625802 | R6: =Walkerhill!P6 -> 26385 | S6: =City!P6 -> 3256 | T6: =Busan!P6 -> 5423 | U6: =Jeju!P6 -> 1641 | V6: =SUM(R6:U6) -> 36705
B7: 40663 | J7: =Walkerhill!K7 -> 175481 | K7: =City!K7 -> 72360 | L7: =Busan!K7 -> 52685.09 | M7: =Jeju!K7 -> 13976 | N7: =SUM(J7:M7) -> 314502.09 | P7: =Segment!K7 -> 0.11098177 | R7: =Walkerhill!P7 -> 26660 | S7: =City!P7 -> 5054 | T7: =Busan!P7 -> 3247 | U7: =Jeju!P7 -> 1747 | V7: =SUM(R7:U7) -> 36708
B8: 40694 | J8: =Walkerhill!K8 -> 189623 | K8: =City!K8 -> 83584 | L8: =Busan!K8 -> 59982.794 | M8: =Jeju!K8 -> 20102 | N8: =SUM(J8:M8) -> 353291.79 | P8: =Segment!K8 -> 0.10125058 | R8: =Walkerhill!P8 -> 25108 | S8: =City!P8 -> 5134 | T8: =Busan!P8 -> 7171 | U8: =Jeju!P8 -> 511 | V8: =SUM(R8:U8) -> 37924
B9: 40724 | J9: =Walkerhill!K9 -> 194966 | K9: =City!K9 -> 69260 | L9: =Busan!K9 -> 43310.78 | M9: =Jeju!K9 -> 20452 | N9: =SUM(J9:M9) -> 327988.78 | P9: =Segment!K9 -> 0.10614692 | R9: =Walkerhill!P9 -> 26046 | S9: =City!P9 -> 4316 | T9: =Busan!P9 -> 3556 | U9: =Jeju!P9 -> 2617 | V9: =SUM(R9:U9) -> 36535
B10: 40755 | J10: =Walkerhill!K10 -> 181896 | K10: =City!K10 -> 78968 | L10: =Busan!K10 -> 56786.571 | M10: =Jeju!K10 -> 24597 | N10: =SUM(J10:M10) -> 342247.57 | P10: =Segment!K10 -> 0.1274925 | R10: =Walkerhill!P10 -> 26975 | S10: =City!P10 -> 8768 | T10: =Busan!P10 -> 8054 | U10: =Jeju!P10 -> 1605 | V10: =SUM(R10:U10) -> 45402
B11: 40786 | J11: =Walkerhill!K11 -> 204482 | K11: =City!K11 -> 72019 | L11: =Busan!K11 -> 51797.435 | M11: =Jeju!K11 -> 28360.8 | N11: =SUM(J11:M11) -> 356659.23 | P11: =Segment!K11 -> 0.12131187 | R11: =Walkerhill!P11 -> 30058 | S11: =City!P11 -> 5874 | T11: =Busan!P11 -> 6129 | U11: =Jeju!P11 -> 3047 | V11: =SUM(R11:U11) -> 45108
B12: 40816 | J12: =Walkerhill!K12 -> 218919 | K12: =City!K12 -> 60239 | L12: =Busan!K12 -> 54601.112 | M12: =Jeju!K12 -> 28258.9 | N12: =SUM(J12:M12) -> 362018.01 | P12: =Segment!K12 -> 0.095188634 | R12: =Walkerhill!P12 -> 19823 | S12: =City!P12 -> 7828 | T12: =Busan!P12 -> 6791 | U12: =Jeju!P12 -> 2220 | V12: =SUM(R12:U12) -> 36662
B13: 40847 | J13: =Walkerhill!K13 -> 288116 | K13: =City!K13 -> 66405 | L13: =Busan!K13 -> 73460.831 | M13: =Jeju!K13 -> 38952 | N13: =SUM(J13:M13) -> 466933.83 | P13: =Segment!K13 -> 0.13187307 | R13: =Walkerhill!P13 -> 39532 | S13: =City!P13 -> 10335 | T13: =Busan!P13 -> 9715 | U13: =Jeju!P13 -> 4348 | V13: =SUM(R13:U13) -> 63930
B14: 40877 | J14: =Walkerhill!K14 -> 204907 | K14: =City!K14 -> 48585 | L14: =Busan!K14 -> 59318.218 | M14: =Jeju!K14 -> 35896.3 | N14: =SUM(J14:M14) -> 348706.52 | P14: =Segment!K14 -> 0.1434358 | R14: =Walkerhill!P14 -> 39365 | S14: =City!P14 -> 6350 | T14: =Busan!P14 -> 5951 | U14: =Jeju!P14 -> 969 | V14: =SUM(R14:U14) -> 52635
